{
 "cells": [
  {
   "cell_type": "code",
   "execution_count": 1,
   "id": "720f1a5f",
   "metadata": {},
   "outputs": [
    {
     "name": "stdout",
     "output_type": "stream",
     "text": [
      "d:\\MachineLearning\\federated_vae\\main\n"
     ]
    }
   ],
   "source": [
    "%cd ."
   ]
  },
  {
   "cell_type": "code",
   "execution_count": 2,
   "id": "c1964b06",
   "metadata": {},
   "outputs": [
    {
     "name": "stderr",
     "output_type": "stream",
     "text": [
      "d:\\Anaconda\\envs\\TMenv\\lib\\site-packages\\tqdm\\auto.py:21: TqdmWarning: IProgress not found. Please update jupyter and ipywidgets. See https://ipywidgets.readthedocs.io/en/stable/user_install.html\n",
      "  from .autonotebook import tqdm as notebook_tqdm\n",
      "2025-07-12 23:21:09,406\tINFO util.py:154 -- Missing packages: ['ipywidgets']. Run `pip install -U ipywidgets`, then restart the notebook server for rich notebook output.\n"
     ]
    },
    {
     "name": "stdout",
     "output_type": "stream",
     "text": [
      "Training on cuda\n",
      "Flower 1.19.0 / PyTorch 2.5.1+cu121\n"
     ]
    }
   ],
   "source": [
    "from collections import OrderedDict\n",
    "from typing import List, Tuple\n",
    "\n",
    "import matplotlib.pyplot as plt\n",
    "import numpy as np\n",
    "import torch\n",
    "import torch.nn as nn\n",
    "import torch.nn.functional as F\n",
    "import torchvision.transforms as transforms\n",
    "from datasets.utils.logging import disable_progress_bar\n",
    "from torch.utils.data import DataLoader\n",
    "\n",
    "import flwr\n",
    "from flwr.client import Client, ClientApp, NumPyClient\n",
    "from flwr.common import Metrics, Context\n",
    "from flwr.server import ServerApp, ServerConfig, ServerAppComponents\n",
    "from flwr.server.strategy import FedAvg\n",
    "from flwr.simulation import run_simulation\n",
    "from flwr_datasets import FederatedDataset\n",
    "\n",
    "DEVICE = \"cuda\" if torch.cuda.is_available() else \"cpu\"\n",
    "print(f\"Training on {DEVICE}\")\n",
    "print(f\"Flower {flwr.__version__} / PyTorch {torch.__version__}\")\n",
    "disable_progress_bar()"
   ]
  },
  {
   "cell_type": "code",
   "execution_count": null,
   "id": "6c028d54",
   "metadata": {},
   "outputs": [
    {
     "name": "stdout",
     "output_type": "stream",
     "text": [
      "train_size:  11314\n",
      "test_size:  7532\n",
      "vocab_size:  5000\n",
      "average length: 110.543\n"
     ]
    },
    {
     "name": "stderr",
     "output_type": "stream",
     "text": [
      "loading train texts: 100%|██████████| 5657/5657 [00:00<00:00, 6586.48it/s]\n",
      "parsing texts: 100%|██████████| 5657/5657 [00:00<00:00, 8763.46it/s]\n",
      "loading train texts: 100%|██████████| 5657/5657 [00:00<00:00, 6141.97it/s]\n",
      "parsing texts: 100%|██████████| 5657/5657 [00:00<00:00, 6692.00it/s]\n"
     ]
    }
   ],
   "source": [
    "NUM_CLIENTS = 2\n",
    "BATCH_SIZE = 256\n",
    "NUM_ROUNDS = 30\n",
    "\n",
    "from test_flwr import get_all_vocab, split_data\n",
    "vocab = get_all_vocab([\"../data/20NG\"])\n",
    "datasets = split_data(dir = \"../data/20NG\", num_split=NUM_CLIENTS, vocab = vocab, batch_size= BATCH_SIZE)"
   ]
  },
  {
   "cell_type": "code",
   "execution_count": 4,
   "id": "805637fd",
   "metadata": {},
   "outputs": [],
   "source": [
    "from model.ETM import ETM\n",
    "from trainer.basic_trainer import BasicTrainer\n",
    "\n",
    "# net = ETM(len(vocab)).to(DEVICE)\n",
    "\n",
    "# trainer = BasicTrainer(model = net, dataset = datasets[0], epochs=NUM_EPOCHS, batch_size=BATCH_SIZE,\n",
    "#                        log_interval=10)\n",
    "\n",
    "# trainer.train()\n"
   ]
  },
  {
   "cell_type": "code",
   "execution_count": 5,
   "id": "d1e79e2d",
   "metadata": {},
   "outputs": [],
   "source": [
    "# res = trainer.get_top_words()\n",
    "# print(res)"
   ]
  },
  {
   "cell_type": "code",
   "execution_count": 6,
   "id": "caebed0f",
   "metadata": {},
   "outputs": [],
   "source": [
    "def set_parameters(net, parameters: List[np.ndarray]):\n",
    "    params_dict = zip(net.state_dict().keys(), parameters)\n",
    "    state_dict = OrderedDict({k: torch.Tensor(v) for k, v in params_dict})\n",
    "    net.load_state_dict(state_dict, strict=True)\n",
    "\n",
    "\n",
    "def get_parameters(net) -> List[np.ndarray]:\n",
    "    return [val.cpu().numpy() for _, val in net.state_dict().items()]"
   ]
  },
  {
   "cell_type": "code",
   "execution_count": null,
   "id": "dfa431d2",
   "metadata": {},
   "outputs": [],
   "source": [
    "from data.basic_dataset import RawDataset\n",
    "class FlowerClient(NumPyClient):\n",
    "  def __init__(self, net, dataset : RawDataset, id):\n",
    "    self.net = net\n",
    "    self.dataset = dataset\n",
    "    self.trainer = BasicTrainer(net, dataset, epochs = 1, log_interval=10, device = DEVICE)\n",
    "    self.id = id\n",
    "    self.save_dir = \"model_parameters/\"\n",
    "    self.round_id = 0\n",
    "\n",
    "  # return the current local model parameters\n",
    "  def get_parameters(self, config):\n",
    "    return get_parameters(self.net)\n",
    "\n",
    "  # receive global parameter, train, return updated model to server\n",
    "  def fit(self, parameters, config):\n",
    "    self.round_id += 1\n",
    "    set_parameters(self.net, parameters)\n",
    "    self.trainer.train(model_name = f\"ETM - Client {self.id}\")\n",
    "\n",
    "    if (self.round_id == NUM_ROUNDS)\n",
    "      self._save_parameters(self.net.parameters())\n",
    "    return get_parameters(self.net), len(self.dataset.train_texts), {}\n",
    "\n",
    "  # receive global parameter, evaluate model from local's data, return the evaluation result\n",
    "  def evaluate(self, parameters, config):\n",
    "    set_parameters(self.net, parameters)\n",
    "    loss, acc = -1, -1\n",
    "    return float(loss), 1, {\"accuracy\":float(acc)}\n",
    "  \n",
    "  def _save_parameters(self, parameters, prefix=\"ETM\"):\n",
    "      \"\"\"Hàm helper để lưu parameters\"\"\"\n",
    "      # Chuyển Flower Parameters sang state_dict\n",
    "      params_dict = zip(self.net.state_dict().keys(), parameters)\n",
    "      state_dict = {k: torch.tensor(v) for k, v in params_dict}\n",
    "        \n",
    "      # Tạo tên file\n",
    "      filename = f\"{prefix}_client{self.id}.pth\"\n",
    "      save_path = self.save_dir + filename\n",
    "        \n",
    "      # Lưu file\n",
    "      torch.save(state_dict, save_path)\n",
    "      print(f\"Saved client{self.id}'s model at {save_path}\")\n",
    "\n",
    "test = FlowerClient(ETM(len(vocab)), datasets[0], 0)"
   ]
  },
  {
   "cell_type": "code",
   "execution_count": 8,
   "id": "08e13914",
   "metadata": {},
   "outputs": [
    {
     "name": "stdout",
     "output_type": "stream",
     "text": [
      "Saved client0's model at model_parameters/ETM_client0.pth\n"
     ]
    }
   ],
   "source": [
    "test._save_parameters(test.net.parameters())"
   ]
  },
  {
   "cell_type": "code",
   "execution_count": 9,
   "id": "8236b702",
   "metadata": {},
   "outputs": [],
   "source": [
    "def client_fn(context: Context) -> Client:\n",
    "    \"\"\"Create a Flower client representing a single organization.\"\"\"\n",
    "\n",
    "    # Load model\n",
    "    net = ETM(len(vocab)).to(DEVICE)\n",
    "\n",
    "    # Load data (CIFAR-10)\n",
    "    # Note: each client gets a different trainloader/valloader, so each client\n",
    "    # will train and evaluate on their own unique data partition\n",
    "    # Read the node_config to fetch data partition associated to this node\n",
    "    partition_id = context.node_config[\"partition-id\"]\n",
    "    dataset = datasets[partition_id]\n",
    "\n",
    "    # Create a single Flower client representing a single organization\n",
    "    # FlowerClient is a subclass of NumPyClient, so we need to call .to_client()\n",
    "    # to convert it to a subclass of `flwr.client.Client`\n",
    "    return FlowerClient(net, dataset, partition_id).to_client()\n",
    "\n",
    "\n",
    "# Create the ClientApp\n",
    "client = ClientApp(client_fn=client_fn)"
   ]
  },
  {
   "cell_type": "code",
   "execution_count": 10,
   "id": "d55018fb",
   "metadata": {},
   "outputs": [
    {
     "name": "stdout",
     "output_type": "stream",
     "text": [
      "<bound method Module.parameters of ETM(\n",
      "  (encoder1): Sequential(\n",
      "    (0): Linear(in_features=5000, out_features=800, bias=True)\n",
      "    (1): ReLU()\n",
      "    (2): Linear(in_features=800, out_features=800, bias=True)\n",
      "    (3): ReLU()\n",
      "    (4): Dropout(p=0.0, inplace=False)\n",
      "  )\n",
      "  (fc21): Linear(in_features=800, out_features=50, bias=True)\n",
      "  (fc22): Linear(in_features=800, out_features=50, bias=True)\n",
      ")>\n"
     ]
    }
   ],
   "source": [
    "print(test.net.parameters)"
   ]
  },
  {
   "cell_type": "code",
   "execution_count": null,
   "id": "233689d6",
   "metadata": {},
   "outputs": [],
   "source": [
    "def server_fn(context: Context) -> ServerAppComponents:\n",
    "    \"\"\"Construct components that set the ServerApp behaviour.\n",
    "\n",
    "    You can use the settings in `context.run_config` to parameterize the\n",
    "    construction of all elements (e.g the strategy or the number of rounds)\n",
    "    wrapped in the returned ServerAppComponents object.\n",
    "    \"\"\"\n",
    "\n",
    "    # Configure the server for 30 rounds of training\n",
    "    config = ServerConfig(num_rounds=NUM_ROUNDS)\n",
    "    # Create FedAvg strategy\n",
    "    strategy = FedAvg(\n",
    "        fraction_fit=1.0,\n",
    "        fraction_evaluate=0.5,\n",
    "        min_fit_clients=NUM_CLIENTS,\n",
    "        min_available_clients=NUM_CLIENTS,\n",
    "    )\n",
    "    return ServerAppComponents(strategy=strategy, config=config)\n",
    "\n",
    "\n",
    "# Create the ServerApp\n",
    "server = ServerApp(server_fn=server_fn)"
   ]
  },
  {
   "cell_type": "code",
   "execution_count": 12,
   "id": "a830fd98",
   "metadata": {},
   "outputs": [],
   "source": [
    "# Specify the resources each of your clients need\n",
    "# By default, each client will be allocated 1x CPU and 0x GPUs\n",
    "backend_config = {\"client_resources\": {\"num_cpus\": 1, \"num_gpus\": 0.0}}\n",
    "\n",
    "# When running on GPU, assign an entire GPU for each client\n",
    "if DEVICE == \"cuda\":\n",
    "    backend_config = {\"client_resources\": {\"num_cpus\": 1, \"num_gpus\": 1.0}}\n",
    "    # Refer to our Flower framework documentation for more details about Flower simulations\n",
    "    # and how to set up the `backend_config`"
   ]
  },
  {
   "cell_type": "code",
   "execution_count": 13,
   "id": "22fadb84",
   "metadata": {},
   "outputs": [
    {
     "name": "stderr",
     "output_type": "stream",
     "text": [
      "\u001b[94mDEBUG 2025-07-12 23:21:26,745\u001b[0m:     Asyncio event loop already running.\n",
      "\u001b[94mDEBUG 2025-07-12 23:21:26,746\u001b[0m:     Logger propagate set to False\n",
      "\u001b[94mDEBUG 2025-07-12 23:21:26,748\u001b[0m:     Pre-registering run with id 1713423872093146814\n",
      "\u001b[94mDEBUG 2025-07-12 23:21:26,750\u001b[0m:     Using InMemoryState\n",
      "\u001b[94mDEBUG 2025-07-12 23:21:26,751\u001b[0m:     Using InMemoryState\n",
      "\u001b[92mINFO 2025-07-12 23:21:26,760\u001b[0m:      Starting Flower ServerApp, config: num_rounds=30, no round_timeout\n",
      "\u001b[94mDEBUG 2025-07-12 23:21:26,764\u001b[0m:     Using InMemoryState\n",
      "\u001b[92mINFO 2025-07-12 23:21:26,766\u001b[0m:      \n",
      "\u001b[94mDEBUG 2025-07-12 23:21:26,766\u001b[0m:     Registered 2 nodes\n",
      "\u001b[94mDEBUG 2025-07-12 23:21:26,767\u001b[0m:     Supported backends: ['ray']\n",
      "\u001b[92mINFO 2025-07-12 23:21:26,769\u001b[0m:      [INIT]\n",
      "\u001b[94mDEBUG 2025-07-12 23:21:26,770\u001b[0m:     Initialising: RayBackend\n",
      "\u001b[92mINFO 2025-07-12 23:21:26,771\u001b[0m:      Requesting initial parameters from one random client\n",
      "\u001b[94mDEBUG 2025-07-12 23:21:26,773\u001b[0m:     Backend config: {'client_resources': {'num_cpus': 1, 'num_gpus': 1.0}, 'init_args': {}, 'actor': {'tensorflow': 0}}\n",
      "2025-07-12 23:21:30,797\tINFO worker.py:1771 -- Started a local Ray instance.\n",
      "\u001b[94mDEBUG 2025-07-12 23:21:32,726\u001b[0m:     Constructed ActorPool with: 1 actors\n",
      "\u001b[94mDEBUG 2025-07-12 23:21:32,727\u001b[0m:     Using InMemoryState\n",
      "\u001b[92mINFO 2025-07-12 23:21:52,296\u001b[0m:      Received initial parameters from one random client\n",
      "\u001b[92mINFO 2025-07-12 23:21:52,304\u001b[0m:      Starting evaluation of initial global parameters\n",
      "\u001b[92mINFO 2025-07-12 23:21:52,305\u001b[0m:      Evaluation returned no results (`None`)\n",
      "\u001b[92mINFO 2025-07-12 23:21:52,305\u001b[0m:      \n",
      "\u001b[92mINFO 2025-07-12 23:21:52,306\u001b[0m:      [ROUND 1]\n",
      "\u001b[92mINFO 2025-07-12 23:21:52,306\u001b[0m:      configure_fit: strategy sampled 2 clients (out of 2)\n"
     ]
    },
    {
     "name": "stdout",
     "output_type": "stream",
     "text": [
      "\u001b[36m(ClientAppActor pid=17872)\u001b[0m Client's model: ETM - Client 0\n",
      "\u001b[36m(ClientAppActor pid=17872)\u001b[0m Epoch: 000 | Loss: 1954.833251953125\n",
      "\u001b[36m(ClientAppActor pid=17872)\u001b[0m {}\n",
      "\u001b[36m(ClientAppActor pid=17872)\u001b[0m Client's model: ETM - Client 1\n",
      "\u001b[36m(ClientAppActor pid=17872)\u001b[0m Epoch: 000 | Loss: 1900.1961669921875\n",
      "\u001b[36m(ClientAppActor pid=17872)\u001b[0m {}\n"
     ]
    },
    {
     "name": "stderr",
     "output_type": "stream",
     "text": [
      "\u001b[92mINFO 2025-07-12 23:22:00,843\u001b[0m:      aggregate_fit: received 2 results and 0 failures\n",
      "\u001b[93mWARNING 2025-07-12 23:22:00,935\u001b[0m:   No fit_metrics_aggregation_fn provided\n",
      "\u001b[92mINFO 2025-07-12 23:22:00,940\u001b[0m:      configure_evaluate: strategy sampled 2 clients (out of 2)\n",
      "\u001b[92mINFO 2025-07-12 23:22:03,836\u001b[0m:      aggregate_evaluate: received 2 results and 0 failures\n",
      "\u001b[93mWARNING 2025-07-12 23:22:03,838\u001b[0m:   No evaluate_metrics_aggregation_fn provided\n",
      "\u001b[92mINFO 2025-07-12 23:22:03,839\u001b[0m:      \n",
      "\u001b[92mINFO 2025-07-12 23:22:03,839\u001b[0m:      [ROUND 2]\n",
      "\u001b[92mINFO 2025-07-12 23:22:03,840\u001b[0m:      configure_fit: strategy sampled 2 clients (out of 2)\n"
     ]
    },
    {
     "name": "stdout",
     "output_type": "stream",
     "text": [
      "\u001b[36m(ClientAppActor pid=17872)\u001b[0m Client's model: ETM - Client 0\n",
      "\u001b[36m(ClientAppActor pid=17872)\u001b[0m Epoch: 000 | Loss: 1610.037353515625\n",
      "\u001b[36m(ClientAppActor pid=17872)\u001b[0m {}\n",
      "\u001b[36m(ClientAppActor pid=17872)\u001b[0m Client's model: ETM - Client 1\n",
      "\u001b[36m(ClientAppActor pid=17872)\u001b[0m Epoch: 000 | Loss: 1565.8861083984375\n",
      "\u001b[36m(ClientAppActor pid=17872)\u001b[0m {}\n"
     ]
    },
    {
     "name": "stderr",
     "output_type": "stream",
     "text": [
      "\u001b[92mINFO 2025-07-12 23:22:11,258\u001b[0m:      aggregate_fit: received 2 results and 0 failures\n",
      "\u001b[92mINFO 2025-07-12 23:22:11,327\u001b[0m:      configure_evaluate: strategy sampled 2 clients (out of 2)\n",
      "\u001b[92mINFO 2025-07-12 23:22:13,522\u001b[0m:      aggregate_evaluate: received 2 results and 0 failures\n",
      "\u001b[92mINFO 2025-07-12 23:22:13,523\u001b[0m:      \n",
      "\u001b[92mINFO 2025-07-12 23:22:13,524\u001b[0m:      [ROUND 3]\n",
      "\u001b[92mINFO 2025-07-12 23:22:13,524\u001b[0m:      configure_fit: strategy sampled 2 clients (out of 2)\n"
     ]
    },
    {
     "name": "stdout",
     "output_type": "stream",
     "text": [
      "\u001b[36m(ClientAppActor pid=17872)\u001b[0m Client's model: ETM - Client 0\n",
      "\u001b[36m(ClientAppActor pid=17872)\u001b[0m Epoch: 000 | Loss: 1389.2437744140625\n",
      "\u001b[36m(ClientAppActor pid=17872)\u001b[0m {}\n",
      "\u001b[36m(ClientAppActor pid=17872)\u001b[0m Client's model: ETM - Client 1\n",
      "\u001b[36m(ClientAppActor pid=17872)\u001b[0m Epoch: 000 | Loss: 1349.533203125\n",
      "\u001b[36m(ClientAppActor pid=17872)\u001b[0m {}\n"
     ]
    },
    {
     "name": "stderr",
     "output_type": "stream",
     "text": [
      "\u001b[92mINFO 2025-07-12 23:22:20,822\u001b[0m:      aggregate_fit: received 2 results and 0 failures\n",
      "\u001b[92mINFO 2025-07-12 23:22:20,893\u001b[0m:      configure_evaluate: strategy sampled 2 clients (out of 2)\n",
      "\u001b[92mINFO 2025-07-12 23:22:24,494\u001b[0m:      aggregate_evaluate: received 2 results and 0 failures\n",
      "\u001b[92mINFO 2025-07-12 23:22:24,504\u001b[0m:      \n",
      "\u001b[92mINFO 2025-07-12 23:22:24,505\u001b[0m:      [ROUND 4]\n",
      "\u001b[92mINFO 2025-07-12 23:22:24,506\u001b[0m:      configure_fit: strategy sampled 2 clients (out of 2)\n"
     ]
    },
    {
     "name": "stdout",
     "output_type": "stream",
     "text": [
      "\u001b[36m(ClientAppActor pid=17872)\u001b[0m Client's model: ETM - Client 0\n",
      "\u001b[36m(ClientAppActor pid=17872)\u001b[0m Epoch: 000 | Loss: 1231.1519775390625\n",
      "\u001b[36m(ClientAppActor pid=17872)\u001b[0m {}\n",
      "\u001b[36m(ClientAppActor pid=17872)\u001b[0m Client's model: ETM - Client 1\n",
      "\u001b[36m(ClientAppActor pid=17872)\u001b[0m Epoch: 000 | Loss: 1200.928466796875\n",
      "\u001b[36m(ClientAppActor pid=17872)\u001b[0m {}\n"
     ]
    },
    {
     "name": "stderr",
     "output_type": "stream",
     "text": [
      "\u001b[92mINFO 2025-07-12 23:22:33,882\u001b[0m:      aggregate_fit: received 2 results and 0 failures\n",
      "\u001b[92mINFO 2025-07-12 23:22:33,938\u001b[0m:      configure_evaluate: strategy sampled 2 clients (out of 2)\n",
      "\u001b[92mINFO 2025-07-12 23:22:37,289\u001b[0m:      aggregate_evaluate: received 2 results and 0 failures\n",
      "\u001b[92mINFO 2025-07-12 23:22:37,290\u001b[0m:      \n",
      "\u001b[92mINFO 2025-07-12 23:22:37,291\u001b[0m:      [ROUND 5]\n",
      "\u001b[92mINFO 2025-07-12 23:22:37,292\u001b[0m:      configure_fit: strategy sampled 2 clients (out of 2)\n"
     ]
    },
    {
     "name": "stdout",
     "output_type": "stream",
     "text": [
      "\u001b[36m(ClientAppActor pid=17872)\u001b[0m Client's model: ETM - Client 0\n",
      "\u001b[36m(ClientAppActor pid=17872)\u001b[0m Epoch: 000 | Loss: 1124.189208984375\n",
      "\u001b[36m(ClientAppActor pid=17872)\u001b[0m {}\n",
      "\u001b[36m(ClientAppActor pid=17872)\u001b[0m Client's model: ETM - Client 1\n",
      "\u001b[36m(ClientAppActor pid=17872)\u001b[0m Epoch: 000 | Loss: 1095.61474609375\n",
      "\u001b[36m(ClientAppActor pid=17872)\u001b[0m {}\n"
     ]
    },
    {
     "name": "stderr",
     "output_type": "stream",
     "text": [
      "\u001b[92mINFO 2025-07-12 23:22:46,042\u001b[0m:      aggregate_fit: received 2 results and 0 failures\n",
      "\u001b[92mINFO 2025-07-12 23:22:46,121\u001b[0m:      configure_evaluate: strategy sampled 2 clients (out of 2)\n",
      "\u001b[92mINFO 2025-07-12 23:22:57,317\u001b[0m:      aggregate_evaluate: received 2 results and 0 failures\n",
      "\u001b[92mINFO 2025-07-12 23:22:58,027\u001b[0m:      \n",
      "\u001b[92mINFO 2025-07-12 23:22:58,127\u001b[0m:      [ROUND 6]\n",
      "\u001b[92mINFO 2025-07-12 23:22:58,127\u001b[0m:      configure_fit: strategy sampled 2 clients (out of 2)\n"
     ]
    },
    {
     "name": "stdout",
     "output_type": "stream",
     "text": [
      "\u001b[36m(ClientAppActor pid=17872)\u001b[0m Client's model: ETM - Client 0\n",
      "\u001b[36m(ClientAppActor pid=17872)\u001b[0m Epoch: 000 | Loss: 1044.543701171875\n",
      "\u001b[36m(ClientAppActor pid=17872)\u001b[0m {}\n",
      "\u001b[36m(ClientAppActor pid=17872)\u001b[0m Client's model: ETM - Client 1\n",
      "\u001b[36m(ClientAppActor pid=17872)\u001b[0m Epoch: 000 | Loss: 1019.7268676757812\n",
      "\u001b[36m(ClientAppActor pid=17872)\u001b[0m {}\n"
     ]
    },
    {
     "name": "stderr",
     "output_type": "stream",
     "text": [
      "\u001b[92mINFO 2025-07-12 23:23:18,579\u001b[0m:      aggregate_fit: received 2 results and 0 failures\n",
      "\u001b[92mINFO 2025-07-12 23:23:18,638\u001b[0m:      configure_evaluate: strategy sampled 2 clients (out of 2)\n",
      "\u001b[92mINFO 2025-07-12 23:23:24,006\u001b[0m:      aggregate_evaluate: received 2 results and 0 failures\n",
      "\u001b[92mINFO 2025-07-12 23:23:24,008\u001b[0m:      \n",
      "\u001b[92mINFO 2025-07-12 23:23:24,008\u001b[0m:      [ROUND 7]\n",
      "\u001b[92mINFO 2025-07-12 23:23:24,008\u001b[0m:      configure_fit: strategy sampled 2 clients (out of 2)\n"
     ]
    },
    {
     "name": "stdout",
     "output_type": "stream",
     "text": [
      "\u001b[36m(ClientAppActor pid=17872)\u001b[0m Client's model: ETM - Client 0\n",
      "\u001b[36m(ClientAppActor pid=17872)\u001b[0m Epoch: 000 | Loss: 987.4068603515625\n",
      "\u001b[36m(ClientAppActor pid=17872)\u001b[0m {}\n",
      "\u001b[36m(ClientAppActor pid=17872)\u001b[0m Client's model: ETM - Client 1\n",
      "\u001b[36m(ClientAppActor pid=17872)\u001b[0m Epoch: 000 | Loss: 963.5377197265625\n",
      "\u001b[36m(ClientAppActor pid=17872)\u001b[0m {}\n"
     ]
    },
    {
     "name": "stderr",
     "output_type": "stream",
     "text": [
      "\u001b[92mINFO 2025-07-12 23:23:42,044\u001b[0m:      aggregate_fit: received 2 results and 0 failures\n",
      "\u001b[92mINFO 2025-07-12 23:23:42,120\u001b[0m:      configure_evaluate: strategy sampled 2 clients (out of 2)\n",
      "\u001b[92mINFO 2025-07-12 23:23:44,858\u001b[0m:      aggregate_evaluate: received 2 results and 0 failures\n",
      "\u001b[92mINFO 2025-07-12 23:23:44,861\u001b[0m:      \n",
      "\u001b[92mINFO 2025-07-12 23:23:44,862\u001b[0m:      [ROUND 8]\n",
      "\u001b[92mINFO 2025-07-12 23:23:44,863\u001b[0m:      configure_fit: strategy sampled 2 clients (out of 2)\n"
     ]
    },
    {
     "name": "stdout",
     "output_type": "stream",
     "text": [
      "\u001b[36m(ClientAppActor pid=17872)\u001b[0m Client's model: ETM - Client 0\n",
      "\u001b[36m(ClientAppActor pid=17872)\u001b[0m Epoch: 000 | Loss: 942.1895751953125\n",
      "\u001b[36m(ClientAppActor pid=17872)\u001b[0m {}\n",
      "\u001b[36m(ClientAppActor pid=17872)\u001b[0m Client's model: ETM - Client 1\n",
      "\u001b[36m(ClientAppActor pid=17872)\u001b[0m Epoch: 000 | Loss: 919.9139404296875\n",
      "\u001b[36m(ClientAppActor pid=17872)\u001b[0m {}\n"
     ]
    },
    {
     "name": "stderr",
     "output_type": "stream",
     "text": [
      "\u001b[33m(raylet)\u001b[0m [2025-07-12 23:24:02,763 C 19496 11764] (raylet.exe) dlmalloc.cc:129:  Check failed: *handle != nullptr CreateFileMapping() failed. GetLastError() = 1455\n",
      "\u001b[33m(raylet)\u001b[0m *** StackTrace Information ***\n",
      "\u001b[33m(raylet)\u001b[0m unknown\n",
      "\u001b[33m(raylet)\u001b[0m \n",
      "\u001b[91mERROR 2025-07-12 23:24:10,501\u001b[0m:     An exception was raised when processing a message by RayBackend\n",
      "\u001b[91mERROR 2025-07-12 23:24:10,507\u001b[0m:     The actor 4c33155849fd78a47e1ec21501000000 is unavailable: The actor is temporarily unavailable: RpcError: RPC Error message: Connection reset; RPC Error details: . The task may or maynot have been executed on the actor.\n",
      "\u001b[91mERROR 2025-07-12 23:24:10,684\u001b[0m:     Traceback (most recent call last):\n",
      "  File \"d:\\Anaconda\\envs\\TMenv\\lib\\site-packages\\flwr\\server\\superlink\\fleet\\vce\\vce_api.py\", line 112, in worker\n",
      "    out_mssg, updated_context = backend.process_message(message, context)\n",
      "  File \"d:\\Anaconda\\envs\\TMenv\\lib\\site-packages\\flwr\\server\\superlink\\fleet\\vce\\backend\\raybackend.py\", line 187, in process_message\n",
      "    raise ex\n",
      "  File \"d:\\Anaconda\\envs\\TMenv\\lib\\site-packages\\flwr\\server\\superlink\\fleet\\vce\\backend\\raybackend.py\", line 175, in process_message\n",
      "    ) = self.pool.fetch_result_and_return_actor_to_pool(future)\n",
      "  File \"d:\\Anaconda\\envs\\TMenv\\lib\\site-packages\\flwr\\simulation\\ray_transport\\ray_actor.py\", line 480, in fetch_result_and_return_actor_to_pool\n",
      "    _, out_mssg, updated_context = ray.get(future)\n",
      "  File \"d:\\Anaconda\\envs\\TMenv\\lib\\site-packages\\ray\\_private\\auto_init_hook.py\", line 21, in auto_init_wrapper\n",
      "    return fn(*args, **kwargs)\n",
      "  File \"d:\\Anaconda\\envs\\TMenv\\lib\\site-packages\\ray\\_private\\client_mode_hook.py\", line 103, in wrapper\n",
      "    return func(*args, **kwargs)\n",
      "  File \"d:\\Anaconda\\envs\\TMenv\\lib\\site-packages\\ray\\_private\\worker.py\", line 2639, in get\n",
      "    values, debugger_breakpoint = worker.get_objects(object_refs, timeout=timeout)\n",
      "  File \"d:\\Anaconda\\envs\\TMenv\\lib\\site-packages\\ray\\_private\\worker.py\", line 866, in get_objects\n",
      "    raise value\n",
      "ray.exceptions.ActorUnavailableError: The actor 4c33155849fd78a47e1ec21501000000 is unavailable: The actor is temporarily unavailable: RpcError: RPC Error message: Connection reset; RPC Error details: . The task may or maynot have been executed on the actor.\n",
      "\n",
      "\u001b[92mINFO 2025-07-12 23:24:10,775\u001b[0m:      aggregate_fit: received 1 results and 1 failures\n",
      "\u001b[92mINFO 2025-07-12 23:24:10,807\u001b[0m:      configure_evaluate: strategy sampled 2 clients (out of 2)\n",
      "\u001b[91mERROR 2025-07-12 23:24:11,340\u001b[0m:     An exception was raised when processing a message by RayBackend\n",
      "\u001b[91mERROR 2025-07-12 23:24:11,341\u001b[0m:     local variable 'future' referenced before assignment\n",
      "\u001b[91mERROR 2025-07-12 23:24:11,399\u001b[0m:     Traceback (most recent call last):\n",
      "  File \"d:\\Anaconda\\envs\\TMenv\\lib\\site-packages\\flwr\\server\\superlink\\fleet\\vce\\backend\\raybackend.py\", line 166, in process_message\n",
      "    future = self.pool.submit(\n",
      "  File \"d:\\Anaconda\\envs\\TMenv\\lib\\site-packages\\flwr\\simulation\\ray_transport\\ray_actor.py\", line 463, in submit\n",
      "    future = actor_fn(actor, app_fn, mssg, cid, context)\n",
      "  File \"d:\\Anaconda\\envs\\TMenv\\lib\\site-packages\\flwr\\server\\superlink\\fleet\\vce\\backend\\raybackend.py\", line 167, in <lambda>\n",
      "    lambda a, a_fn, mssg, cid, state: a.run.remote(a_fn, mssg, cid, state),\n",
      "  File \"d:\\Anaconda\\envs\\TMenv\\lib\\site-packages\\ray\\actor.py\", line 202, in remote\n",
      "    return self._remote(args, kwargs)\n",
      "  File \"d:\\Anaconda\\envs\\TMenv\\lib\\site-packages\\ray\\_private\\auto_init_hook.py\", line 21, in auto_init_wrapper\n",
      "    return fn(*args, **kwargs)\n",
      "  File \"d:\\Anaconda\\envs\\TMenv\\lib\\site-packages\\ray\\util\\tracing\\tracing_helper.py\", line 426, in _start_span\n",
      "    return method(self, args, kwargs, *_args, **_kwargs)\n",
      "  File \"d:\\Anaconda\\envs\\TMenv\\lib\\site-packages\\ray\\actor.py\", line 330, in _remote\n",
      "    return invocation(args, kwargs)\n",
      "  File \"d:\\Anaconda\\envs\\TMenv\\lib\\site-packages\\ray\\actor.py\", line 311, in invocation\n",
      "    return actor._actor_method_call(\n",
      "  File \"d:\\Anaconda\\envs\\TMenv\\lib\\site-packages\\ray\\actor.py\", line 1463, in _actor_method_call\n",
      "    object_refs = worker.core_worker.submit_actor_task(\n",
      "  File \"python\\ray\\_raylet.pyx\", line 4250, in ray._raylet.CoreWorker.submit_actor_task\n",
      "  File \"python\\ray\\_raylet.pyx\", line 4255, in ray._raylet.CoreWorker.submit_actor_task\n",
      "  File \"python\\ray\\_raylet.pyx\", line 871, in ray._raylet.prepare_args_and_increment_put_refs\n",
      "  File \"python\\ray\\_raylet.pyx\", line 862, in ray._raylet.prepare_args_and_increment_put_refs\n",
      "  File \"python\\ray\\_raylet.pyx\", line 959, in ray._raylet.prepare_args_internal\n",
      "  File \"python\\ray\\_raylet.pyx\", line 3758, in ray._raylet.CoreWorker.put_serialized_object_and_increment_local_ref\n",
      "  File \"python\\ray\\_raylet.pyx\", line 3547, in ray._raylet.CoreWorker._create_put_buffer\n",
      "  File \"python\\ray\\_raylet.pyx\", line 581, in ray._raylet.check_status\n",
      "OSError: Unknown error\n",
      "\n",
      "During handling of the above exception, another exception occurred:\n",
      "\n",
      "Traceback (most recent call last):\n",
      "  File \"d:\\Anaconda\\envs\\TMenv\\lib\\site-packages\\flwr\\server\\superlink\\fleet\\vce\\vce_api.py\", line 112, in worker\n",
      "    out_mssg, updated_context = backend.process_message(message, context)\n",
      "  File \"d:\\Anaconda\\envs\\TMenv\\lib\\site-packages\\flwr\\server\\superlink\\fleet\\vce\\backend\\raybackend.py\", line 186, in process_message\n",
      "    self.pool.add_actor_back_to_pool(future)\n",
      "UnboundLocalError: local variable 'future' referenced before assignment\n",
      "\n",
      "\u001b[91mERROR 2025-07-12 23:24:11,401\u001b[0m:     An exception was raised when processing a message by RayBackend\n",
      "\u001b[91mERROR 2025-07-12 23:24:11,401\u001b[0m:     local variable 'future' referenced before assignment\n",
      "\u001b[91mERROR 2025-07-12 23:24:11,403\u001b[0m:     Traceback (most recent call last):\n",
      "  File \"d:\\Anaconda\\envs\\TMenv\\lib\\site-packages\\flwr\\server\\superlink\\fleet\\vce\\backend\\raybackend.py\", line 166, in process_message\n",
      "    future = self.pool.submit(\n",
      "  File \"d:\\Anaconda\\envs\\TMenv\\lib\\site-packages\\flwr\\simulation\\ray_transport\\ray_actor.py\", line 460, in submit\n",
      "    actor = self.pool.pop()\n",
      "IndexError: pop from empty list\n",
      "\n",
      "During handling of the above exception, another exception occurred:\n",
      "\n",
      "Traceback (most recent call last):\n",
      "  File \"d:\\Anaconda\\envs\\TMenv\\lib\\site-packages\\flwr\\server\\superlink\\fleet\\vce\\vce_api.py\", line 112, in worker\n",
      "    out_mssg, updated_context = backend.process_message(message, context)\n",
      "  File \"d:\\Anaconda\\envs\\TMenv\\lib\\site-packages\\flwr\\server\\superlink\\fleet\\vce\\backend\\raybackend.py\", line 186, in process_message\n",
      "    self.pool.add_actor_back_to_pool(future)\n",
      "UnboundLocalError: local variable 'future' referenced before assignment\n",
      "\n",
      "\u001b[92mINFO 2025-07-12 23:24:11,416\u001b[0m:      aggregate_evaluate: received 0 results and 2 failures\n",
      "\u001b[92mINFO 2025-07-12 23:24:11,417\u001b[0m:      \n",
      "\u001b[92mINFO 2025-07-12 23:24:11,418\u001b[0m:      [ROUND 9]\n",
      "\u001b[92mINFO 2025-07-12 23:24:11,418\u001b[0m:      configure_fit: strategy sampled 2 clients (out of 2)\n",
      "\u001b[91mERROR 2025-07-12 23:24:11,526\u001b[0m:     An exception was raised when processing a message by RayBackend\n",
      "\u001b[91mERROR 2025-07-12 23:24:11,527\u001b[0m:     local variable 'future' referenced before assignment\n",
      "\u001b[91mERROR 2025-07-12 23:24:11,529\u001b[0m:     Traceback (most recent call last):\n",
      "  File \"d:\\Anaconda\\envs\\TMenv\\lib\\site-packages\\flwr\\server\\superlink\\fleet\\vce\\backend\\raybackend.py\", line 166, in process_message\n",
      "    future = self.pool.submit(\n",
      "  File \"d:\\Anaconda\\envs\\TMenv\\lib\\site-packages\\flwr\\simulation\\ray_transport\\ray_actor.py\", line 460, in submit\n",
      "    actor = self.pool.pop()\n",
      "IndexError: pop from empty list\n",
      "\n",
      "During handling of the above exception, another exception occurred:\n",
      "\n",
      "Traceback (most recent call last):\n",
      "  File \"d:\\Anaconda\\envs\\TMenv\\lib\\site-packages\\flwr\\server\\superlink\\fleet\\vce\\vce_api.py\", line 112, in worker\n",
      "    out_mssg, updated_context = backend.process_message(message, context)\n",
      "  File \"d:\\Anaconda\\envs\\TMenv\\lib\\site-packages\\flwr\\server\\superlink\\fleet\\vce\\backend\\raybackend.py\", line 186, in process_message\n",
      "    self.pool.add_actor_back_to_pool(future)\n",
      "UnboundLocalError: local variable 'future' referenced before assignment\n",
      "\n",
      "\u001b[91mERROR 2025-07-12 23:24:11,529\u001b[0m:     An exception was raised when processing a message by RayBackend\n",
      "\u001b[91mERROR 2025-07-12 23:24:11,530\u001b[0m:     local variable 'future' referenced before assignment\n",
      "\u001b[91mERROR 2025-07-12 23:24:11,531\u001b[0m:     Traceback (most recent call last):\n",
      "  File \"d:\\Anaconda\\envs\\TMenv\\lib\\site-packages\\flwr\\server\\superlink\\fleet\\vce\\backend\\raybackend.py\", line 166, in process_message\n",
      "    future = self.pool.submit(\n",
      "  File \"d:\\Anaconda\\envs\\TMenv\\lib\\site-packages\\flwr\\simulation\\ray_transport\\ray_actor.py\", line 460, in submit\n",
      "    actor = self.pool.pop()\n",
      "IndexError: pop from empty list\n",
      "\n",
      "During handling of the above exception, another exception occurred:\n",
      "\n",
      "Traceback (most recent call last):\n",
      "  File \"d:\\Anaconda\\envs\\TMenv\\lib\\site-packages\\flwr\\server\\superlink\\fleet\\vce\\vce_api.py\", line 112, in worker\n",
      "    out_mssg, updated_context = backend.process_message(message, context)\n",
      "  File \"d:\\Anaconda\\envs\\TMenv\\lib\\site-packages\\flwr\\server\\superlink\\fleet\\vce\\backend\\raybackend.py\", line 186, in process_message\n",
      "    self.pool.add_actor_back_to_pool(future)\n",
      "UnboundLocalError: local variable 'future' referenced before assignment\n",
      "\n",
      "\u001b[92mINFO 2025-07-12 23:24:11,635\u001b[0m:      aggregate_fit: received 0 results and 2 failures\n",
      "\u001b[92mINFO 2025-07-12 23:24:11,639\u001b[0m:      configure_evaluate: strategy sampled 2 clients (out of 2)\n",
      "\u001b[91mERROR 2025-07-12 23:24:11,741\u001b[0m:     An exception was raised when processing a message by RayBackend\n",
      "\u001b[91mERROR 2025-07-12 23:24:11,742\u001b[0m:     local variable 'future' referenced before assignment\n",
      "\u001b[91mERROR 2025-07-12 23:24:11,743\u001b[0m:     Traceback (most recent call last):\n",
      "  File \"d:\\Anaconda\\envs\\TMenv\\lib\\site-packages\\flwr\\server\\superlink\\fleet\\vce\\backend\\raybackend.py\", line 166, in process_message\n",
      "    future = self.pool.submit(\n",
      "  File \"d:\\Anaconda\\envs\\TMenv\\lib\\site-packages\\flwr\\simulation\\ray_transport\\ray_actor.py\", line 460, in submit\n",
      "    actor = self.pool.pop()\n",
      "IndexError: pop from empty list\n",
      "\n",
      "During handling of the above exception, another exception occurred:\n",
      "\n",
      "Traceback (most recent call last):\n",
      "  File \"d:\\Anaconda\\envs\\TMenv\\lib\\site-packages\\flwr\\server\\superlink\\fleet\\vce\\vce_api.py\", line 112, in worker\n",
      "    out_mssg, updated_context = backend.process_message(message, context)\n",
      "  File \"d:\\Anaconda\\envs\\TMenv\\lib\\site-packages\\flwr\\server\\superlink\\fleet\\vce\\backend\\raybackend.py\", line 186, in process_message\n",
      "    self.pool.add_actor_back_to_pool(future)\n",
      "UnboundLocalError: local variable 'future' referenced before assignment\n",
      "\n",
      "\u001b[91mERROR 2025-07-12 23:24:11,744\u001b[0m:     An exception was raised when processing a message by RayBackend\n",
      "\u001b[91mERROR 2025-07-12 23:24:11,745\u001b[0m:     local variable 'future' referenced before assignment\n",
      "\u001b[91mERROR 2025-07-12 23:24:11,746\u001b[0m:     Traceback (most recent call last):\n",
      "  File \"d:\\Anaconda\\envs\\TMenv\\lib\\site-packages\\flwr\\server\\superlink\\fleet\\vce\\backend\\raybackend.py\", line 166, in process_message\n",
      "    future = self.pool.submit(\n",
      "  File \"d:\\Anaconda\\envs\\TMenv\\lib\\site-packages\\flwr\\simulation\\ray_transport\\ray_actor.py\", line 460, in submit\n",
      "    actor = self.pool.pop()\n",
      "IndexError: pop from empty list\n",
      "\n",
      "During handling of the above exception, another exception occurred:\n",
      "\n",
      "Traceback (most recent call last):\n",
      "  File \"d:\\Anaconda\\envs\\TMenv\\lib\\site-packages\\flwr\\server\\superlink\\fleet\\vce\\vce_api.py\", line 112, in worker\n",
      "    out_mssg, updated_context = backend.process_message(message, context)\n",
      "  File \"d:\\Anaconda\\envs\\TMenv\\lib\\site-packages\\flwr\\server\\superlink\\fleet\\vce\\backend\\raybackend.py\", line 186, in process_message\n",
      "    self.pool.add_actor_back_to_pool(future)\n",
      "UnboundLocalError: local variable 'future' referenced before assignment\n",
      "\n",
      "\u001b[92mINFO 2025-07-12 23:24:11,757\u001b[0m:      aggregate_evaluate: received 0 results and 2 failures\n",
      "\u001b[92mINFO 2025-07-12 23:24:11,758\u001b[0m:      \n",
      "\u001b[92mINFO 2025-07-12 23:24:11,759\u001b[0m:      [ROUND 10]\n",
      "\u001b[92mINFO 2025-07-12 23:24:11,760\u001b[0m:      configure_fit: strategy sampled 2 clients (out of 2)\n",
      "\u001b[91mERROR 2025-07-12 23:24:11,850\u001b[0m:     An exception was raised when processing a message by RayBackend\n",
      "\u001b[91mERROR 2025-07-12 23:24:11,851\u001b[0m:     local variable 'future' referenced before assignment\n",
      "\u001b[91mERROR 2025-07-12 23:24:11,852\u001b[0m:     Traceback (most recent call last):\n",
      "  File \"d:\\Anaconda\\envs\\TMenv\\lib\\site-packages\\flwr\\server\\superlink\\fleet\\vce\\backend\\raybackend.py\", line 166, in process_message\n",
      "    future = self.pool.submit(\n",
      "  File \"d:\\Anaconda\\envs\\TMenv\\lib\\site-packages\\flwr\\simulation\\ray_transport\\ray_actor.py\", line 460, in submit\n",
      "    actor = self.pool.pop()\n",
      "IndexError: pop from empty list\n",
      "\n",
      "During handling of the above exception, another exception occurred:\n",
      "\n",
      "Traceback (most recent call last):\n",
      "  File \"d:\\Anaconda\\envs\\TMenv\\lib\\site-packages\\flwr\\server\\superlink\\fleet\\vce\\vce_api.py\", line 112, in worker\n",
      "    out_mssg, updated_context = backend.process_message(message, context)\n",
      "  File \"d:\\Anaconda\\envs\\TMenv\\lib\\site-packages\\flwr\\server\\superlink\\fleet\\vce\\backend\\raybackend.py\", line 186, in process_message\n",
      "    self.pool.add_actor_back_to_pool(future)\n",
      "UnboundLocalError: local variable 'future' referenced before assignment\n",
      "\n",
      "\u001b[91mERROR 2025-07-12 23:24:11,852\u001b[0m:     An exception was raised when processing a message by RayBackend\n",
      "\u001b[91mERROR 2025-07-12 23:24:11,853\u001b[0m:     local variable 'future' referenced before assignment\n",
      "\u001b[91mERROR 2025-07-12 23:24:11,854\u001b[0m:     Traceback (most recent call last):\n",
      "  File \"d:\\Anaconda\\envs\\TMenv\\lib\\site-packages\\flwr\\server\\superlink\\fleet\\vce\\backend\\raybackend.py\", line 166, in process_message\n",
      "    future = self.pool.submit(\n",
      "  File \"d:\\Anaconda\\envs\\TMenv\\lib\\site-packages\\flwr\\simulation\\ray_transport\\ray_actor.py\", line 460, in submit\n",
      "    actor = self.pool.pop()\n",
      "IndexError: pop from empty list\n",
      "\n",
      "During handling of the above exception, another exception occurred:\n",
      "\n",
      "Traceback (most recent call last):\n",
      "  File \"d:\\Anaconda\\envs\\TMenv\\lib\\site-packages\\flwr\\server\\superlink\\fleet\\vce\\vce_api.py\", line 112, in worker\n",
      "    out_mssg, updated_context = backend.process_message(message, context)\n",
      "  File \"d:\\Anaconda\\envs\\TMenv\\lib\\site-packages\\flwr\\server\\superlink\\fleet\\vce\\backend\\raybackend.py\", line 186, in process_message\n",
      "    self.pool.add_actor_back_to_pool(future)\n",
      "UnboundLocalError: local variable 'future' referenced before assignment\n",
      "\n",
      "\u001b[92mINFO 2025-07-12 23:24:11,866\u001b[0m:      aggregate_fit: received 0 results and 2 failures\n",
      "\u001b[92mINFO 2025-07-12 23:24:11,867\u001b[0m:      configure_evaluate: strategy sampled 2 clients (out of 2)\n",
      "\u001b[91mERROR 2025-07-12 23:24:11,960\u001b[0m:     An exception was raised when processing a message by RayBackend\n",
      "\u001b[91mERROR 2025-07-12 23:24:11,961\u001b[0m:     local variable 'future' referenced before assignment\n",
      "\u001b[91mERROR 2025-07-12 23:24:11,962\u001b[0m:     Traceback (most recent call last):\n",
      "  File \"d:\\Anaconda\\envs\\TMenv\\lib\\site-packages\\flwr\\server\\superlink\\fleet\\vce\\backend\\raybackend.py\", line 166, in process_message\n",
      "    future = self.pool.submit(\n",
      "  File \"d:\\Anaconda\\envs\\TMenv\\lib\\site-packages\\flwr\\simulation\\ray_transport\\ray_actor.py\", line 460, in submit\n",
      "    actor = self.pool.pop()\n",
      "IndexError: pop from empty list\n",
      "\n",
      "During handling of the above exception, another exception occurred:\n",
      "\n",
      "Traceback (most recent call last):\n",
      "  File \"d:\\Anaconda\\envs\\TMenv\\lib\\site-packages\\flwr\\server\\superlink\\fleet\\vce\\vce_api.py\", line 112, in worker\n",
      "    out_mssg, updated_context = backend.process_message(message, context)\n",
      "  File \"d:\\Anaconda\\envs\\TMenv\\lib\\site-packages\\flwr\\server\\superlink\\fleet\\vce\\backend\\raybackend.py\", line 186, in process_message\n",
      "    self.pool.add_actor_back_to_pool(future)\n",
      "UnboundLocalError: local variable 'future' referenced before assignment\n",
      "\n",
      "\u001b[91mERROR 2025-07-12 23:24:11,964\u001b[0m:     An exception was raised when processing a message by RayBackend\n",
      "\u001b[91mERROR 2025-07-12 23:24:11,964\u001b[0m:     local variable 'future' referenced before assignment\n",
      "\u001b[91mERROR 2025-07-12 23:24:11,966\u001b[0m:     Traceback (most recent call last):\n",
      "  File \"d:\\Anaconda\\envs\\TMenv\\lib\\site-packages\\flwr\\server\\superlink\\fleet\\vce\\backend\\raybackend.py\", line 166, in process_message\n",
      "    future = self.pool.submit(\n",
      "  File \"d:\\Anaconda\\envs\\TMenv\\lib\\site-packages\\flwr\\simulation\\ray_transport\\ray_actor.py\", line 460, in submit\n",
      "    actor = self.pool.pop()\n",
      "IndexError: pop from empty list\n",
      "\n",
      "During handling of the above exception, another exception occurred:\n",
      "\n",
      "Traceback (most recent call last):\n",
      "  File \"d:\\Anaconda\\envs\\TMenv\\lib\\site-packages\\flwr\\server\\superlink\\fleet\\vce\\vce_api.py\", line 112, in worker\n",
      "    out_mssg, updated_context = backend.process_message(message, context)\n",
      "  File \"d:\\Anaconda\\envs\\TMenv\\lib\\site-packages\\flwr\\server\\superlink\\fleet\\vce\\backend\\raybackend.py\", line 186, in process_message\n",
      "    self.pool.add_actor_back_to_pool(future)\n",
      "UnboundLocalError: local variable 'future' referenced before assignment\n",
      "\n",
      "\u001b[92mINFO 2025-07-12 23:24:11,975\u001b[0m:      aggregate_evaluate: received 0 results and 2 failures\n",
      "\u001b[92mINFO 2025-07-12 23:24:11,977\u001b[0m:      \n",
      "\u001b[92mINFO 2025-07-12 23:24:11,977\u001b[0m:      [ROUND 11]\n",
      "\u001b[92mINFO 2025-07-12 23:24:11,978\u001b[0m:      configure_fit: strategy sampled 2 clients (out of 2)\n",
      "\u001b[91mERROR 2025-07-12 23:24:12,068\u001b[0m:     An exception was raised when processing a message by RayBackend\n",
      "\u001b[91mERROR 2025-07-12 23:24:12,069\u001b[0m:     local variable 'future' referenced before assignment\n",
      "\u001b[91mERROR 2025-07-12 23:24:12,070\u001b[0m:     Traceback (most recent call last):\n",
      "  File \"d:\\Anaconda\\envs\\TMenv\\lib\\site-packages\\flwr\\server\\superlink\\fleet\\vce\\backend\\raybackend.py\", line 166, in process_message\n",
      "    future = self.pool.submit(\n",
      "  File \"d:\\Anaconda\\envs\\TMenv\\lib\\site-packages\\flwr\\simulation\\ray_transport\\ray_actor.py\", line 460, in submit\n",
      "    actor = self.pool.pop()\n",
      "IndexError: pop from empty list\n",
      "\n",
      "During handling of the above exception, another exception occurred:\n",
      "\n",
      "Traceback (most recent call last):\n",
      "  File \"d:\\Anaconda\\envs\\TMenv\\lib\\site-packages\\flwr\\server\\superlink\\fleet\\vce\\vce_api.py\", line 112, in worker\n",
      "    out_mssg, updated_context = backend.process_message(message, context)\n",
      "  File \"d:\\Anaconda\\envs\\TMenv\\lib\\site-packages\\flwr\\server\\superlink\\fleet\\vce\\backend\\raybackend.py\", line 186, in process_message\n",
      "    self.pool.add_actor_back_to_pool(future)\n",
      "UnboundLocalError: local variable 'future' referenced before assignment\n",
      "\n",
      "\u001b[91mERROR 2025-07-12 23:24:12,070\u001b[0m:     An exception was raised when processing a message by RayBackend\n",
      "\u001b[91mERROR 2025-07-12 23:24:12,071\u001b[0m:     local variable 'future' referenced before assignment\n",
      "\u001b[91mERROR 2025-07-12 23:24:12,072\u001b[0m:     Traceback (most recent call last):\n",
      "  File \"d:\\Anaconda\\envs\\TMenv\\lib\\site-packages\\flwr\\server\\superlink\\fleet\\vce\\backend\\raybackend.py\", line 166, in process_message\n",
      "    future = self.pool.submit(\n",
      "  File \"d:\\Anaconda\\envs\\TMenv\\lib\\site-packages\\flwr\\simulation\\ray_transport\\ray_actor.py\", line 460, in submit\n",
      "    actor = self.pool.pop()\n",
      "IndexError: pop from empty list\n",
      "\n",
      "During handling of the above exception, another exception occurred:\n",
      "\n",
      "Traceback (most recent call last):\n",
      "  File \"d:\\Anaconda\\envs\\TMenv\\lib\\site-packages\\flwr\\server\\superlink\\fleet\\vce\\vce_api.py\", line 112, in worker\n",
      "    out_mssg, updated_context = backend.process_message(message, context)\n",
      "  File \"d:\\Anaconda\\envs\\TMenv\\lib\\site-packages\\flwr\\server\\superlink\\fleet\\vce\\backend\\raybackend.py\", line 186, in process_message\n",
      "    self.pool.add_actor_back_to_pool(future)\n",
      "UnboundLocalError: local variable 'future' referenced before assignment\n",
      "\n",
      "\u001b[92mINFO 2025-07-12 23:24:12,083\u001b[0m:      aggregate_fit: received 0 results and 2 failures\n",
      "\u001b[92mINFO 2025-07-12 23:24:12,084\u001b[0m:      configure_evaluate: strategy sampled 2 clients (out of 2)\n",
      "\u001b[91mERROR 2025-07-12 23:24:12,176\u001b[0m:     An exception was raised when processing a message by RayBackend\n",
      "\u001b[91mERROR 2025-07-12 23:24:12,177\u001b[0m:     local variable 'future' referenced before assignment\n",
      "\u001b[91mERROR 2025-07-12 23:24:12,179\u001b[0m:     Traceback (most recent call last):\n",
      "  File \"d:\\Anaconda\\envs\\TMenv\\lib\\site-packages\\flwr\\server\\superlink\\fleet\\vce\\backend\\raybackend.py\", line 166, in process_message\n",
      "    future = self.pool.submit(\n",
      "  File \"d:\\Anaconda\\envs\\TMenv\\lib\\site-packages\\flwr\\simulation\\ray_transport\\ray_actor.py\", line 460, in submit\n",
      "    actor = self.pool.pop()\n",
      "IndexError: pop from empty list\n",
      "\n",
      "During handling of the above exception, another exception occurred:\n",
      "\n",
      "Traceback (most recent call last):\n",
      "  File \"d:\\Anaconda\\envs\\TMenv\\lib\\site-packages\\flwr\\server\\superlink\\fleet\\vce\\vce_api.py\", line 112, in worker\n",
      "    out_mssg, updated_context = backend.process_message(message, context)\n",
      "  File \"d:\\Anaconda\\envs\\TMenv\\lib\\site-packages\\flwr\\server\\superlink\\fleet\\vce\\backend\\raybackend.py\", line 186, in process_message\n",
      "    self.pool.add_actor_back_to_pool(future)\n",
      "UnboundLocalError: local variable 'future' referenced before assignment\n",
      "\n",
      "\u001b[91mERROR 2025-07-12 23:24:12,179\u001b[0m:     An exception was raised when processing a message by RayBackend\n",
      "\u001b[91mERROR 2025-07-12 23:24:12,180\u001b[0m:     local variable 'future' referenced before assignment\n",
      "\u001b[91mERROR 2025-07-12 23:24:12,181\u001b[0m:     Traceback (most recent call last):\n",
      "  File \"d:\\Anaconda\\envs\\TMenv\\lib\\site-packages\\flwr\\server\\superlink\\fleet\\vce\\backend\\raybackend.py\", line 166, in process_message\n",
      "    future = self.pool.submit(\n",
      "  File \"d:\\Anaconda\\envs\\TMenv\\lib\\site-packages\\flwr\\simulation\\ray_transport\\ray_actor.py\", line 460, in submit\n",
      "    actor = self.pool.pop()\n",
      "IndexError: pop from empty list\n",
      "\n",
      "During handling of the above exception, another exception occurred:\n",
      "\n",
      "Traceback (most recent call last):\n",
      "  File \"d:\\Anaconda\\envs\\TMenv\\lib\\site-packages\\flwr\\server\\superlink\\fleet\\vce\\vce_api.py\", line 112, in worker\n",
      "    out_mssg, updated_context = backend.process_message(message, context)\n",
      "  File \"d:\\Anaconda\\envs\\TMenv\\lib\\site-packages\\flwr\\server\\superlink\\fleet\\vce\\backend\\raybackend.py\", line 186, in process_message\n",
      "    self.pool.add_actor_back_to_pool(future)\n",
      "UnboundLocalError: local variable 'future' referenced before assignment\n",
      "\n",
      "\u001b[92mINFO 2025-07-12 23:24:12,192\u001b[0m:      aggregate_evaluate: received 0 results and 2 failures\n",
      "\u001b[92mINFO 2025-07-12 23:24:12,193\u001b[0m:      \n",
      "\u001b[92mINFO 2025-07-12 23:24:12,194\u001b[0m:      [ROUND 12]\n",
      "\u001b[92mINFO 2025-07-12 23:24:12,194\u001b[0m:      configure_fit: strategy sampled 2 clients (out of 2)\n",
      "\u001b[91mERROR 2025-07-12 23:24:12,282\u001b[0m:     An exception was raised when processing a message by RayBackend\n",
      "\u001b[91mERROR 2025-07-12 23:24:12,283\u001b[0m:     local variable 'future' referenced before assignment\n",
      "\u001b[91mERROR 2025-07-12 23:24:12,284\u001b[0m:     Traceback (most recent call last):\n",
      "  File \"d:\\Anaconda\\envs\\TMenv\\lib\\site-packages\\flwr\\server\\superlink\\fleet\\vce\\backend\\raybackend.py\", line 166, in process_message\n",
      "    future = self.pool.submit(\n",
      "  File \"d:\\Anaconda\\envs\\TMenv\\lib\\site-packages\\flwr\\simulation\\ray_transport\\ray_actor.py\", line 460, in submit\n",
      "    actor = self.pool.pop()\n",
      "IndexError: pop from empty list\n",
      "\n",
      "During handling of the above exception, another exception occurred:\n",
      "\n",
      "Traceback (most recent call last):\n",
      "  File \"d:\\Anaconda\\envs\\TMenv\\lib\\site-packages\\flwr\\server\\superlink\\fleet\\vce\\vce_api.py\", line 112, in worker\n",
      "    out_mssg, updated_context = backend.process_message(message, context)\n",
      "  File \"d:\\Anaconda\\envs\\TMenv\\lib\\site-packages\\flwr\\server\\superlink\\fleet\\vce\\backend\\raybackend.py\", line 186, in process_message\n",
      "    self.pool.add_actor_back_to_pool(future)\n",
      "UnboundLocalError: local variable 'future' referenced before assignment\n",
      "\n",
      "\u001b[91mERROR 2025-07-12 23:24:12,284\u001b[0m:     An exception was raised when processing a message by RayBackend\n",
      "\u001b[91mERROR 2025-07-12 23:24:12,285\u001b[0m:     local variable 'future' referenced before assignment\n",
      "\u001b[91mERROR 2025-07-12 23:24:12,285\u001b[0m:     Traceback (most recent call last):\n",
      "  File \"d:\\Anaconda\\envs\\TMenv\\lib\\site-packages\\flwr\\server\\superlink\\fleet\\vce\\backend\\raybackend.py\", line 166, in process_message\n",
      "    future = self.pool.submit(\n",
      "  File \"d:\\Anaconda\\envs\\TMenv\\lib\\site-packages\\flwr\\simulation\\ray_transport\\ray_actor.py\", line 460, in submit\n",
      "    actor = self.pool.pop()\n",
      "IndexError: pop from empty list\n",
      "\n",
      "During handling of the above exception, another exception occurred:\n",
      "\n",
      "Traceback (most recent call last):\n",
      "  File \"d:\\Anaconda\\envs\\TMenv\\lib\\site-packages\\flwr\\server\\superlink\\fleet\\vce\\vce_api.py\", line 112, in worker\n",
      "    out_mssg, updated_context = backend.process_message(message, context)\n",
      "  File \"d:\\Anaconda\\envs\\TMenv\\lib\\site-packages\\flwr\\server\\superlink\\fleet\\vce\\backend\\raybackend.py\", line 186, in process_message\n",
      "    self.pool.add_actor_back_to_pool(future)\n",
      "UnboundLocalError: local variable 'future' referenced before assignment\n",
      "\n",
      "\u001b[92mINFO 2025-07-12 23:24:12,313\u001b[0m:      aggregate_fit: received 0 results and 2 failures\n",
      "\u001b[92mINFO 2025-07-12 23:24:12,315\u001b[0m:      configure_evaluate: strategy sampled 2 clients (out of 2)\n",
      "\u001b[91mERROR 2025-07-12 23:24:12,392\u001b[0m:     An exception was raised when processing a message by RayBackend\n",
      "\u001b[91mERROR 2025-07-12 23:24:12,393\u001b[0m:     local variable 'future' referenced before assignment\n",
      "\u001b[91mERROR 2025-07-12 23:24:12,394\u001b[0m:     Traceback (most recent call last):\n",
      "  File \"d:\\Anaconda\\envs\\TMenv\\lib\\site-packages\\flwr\\server\\superlink\\fleet\\vce\\backend\\raybackend.py\", line 166, in process_message\n",
      "    future = self.pool.submit(\n",
      "  File \"d:\\Anaconda\\envs\\TMenv\\lib\\site-packages\\flwr\\simulation\\ray_transport\\ray_actor.py\", line 460, in submit\n",
      "    actor = self.pool.pop()\n",
      "IndexError: pop from empty list\n",
      "\n",
      "During handling of the above exception, another exception occurred:\n",
      "\n",
      "Traceback (most recent call last):\n",
      "  File \"d:\\Anaconda\\envs\\TMenv\\lib\\site-packages\\flwr\\server\\superlink\\fleet\\vce\\vce_api.py\", line 112, in worker\n",
      "    out_mssg, updated_context = backend.process_message(message, context)\n",
      "  File \"d:\\Anaconda\\envs\\TMenv\\lib\\site-packages\\flwr\\server\\superlink\\fleet\\vce\\backend\\raybackend.py\", line 186, in process_message\n",
      "    self.pool.add_actor_back_to_pool(future)\n",
      "UnboundLocalError: local variable 'future' referenced before assignment\n",
      "\n",
      "\u001b[91mERROR 2025-07-12 23:24:12,395\u001b[0m:     An exception was raised when processing a message by RayBackend\n",
      "\u001b[91mERROR 2025-07-12 23:24:12,395\u001b[0m:     local variable 'future' referenced before assignment\n",
      "\u001b[91mERROR 2025-07-12 23:24:12,396\u001b[0m:     Traceback (most recent call last):\n",
      "  File \"d:\\Anaconda\\envs\\TMenv\\lib\\site-packages\\flwr\\server\\superlink\\fleet\\vce\\backend\\raybackend.py\", line 166, in process_message\n",
      "    future = self.pool.submit(\n",
      "  File \"d:\\Anaconda\\envs\\TMenv\\lib\\site-packages\\flwr\\simulation\\ray_transport\\ray_actor.py\", line 460, in submit\n",
      "    actor = self.pool.pop()\n",
      "IndexError: pop from empty list\n",
      "\n",
      "During handling of the above exception, another exception occurred:\n",
      "\n",
      "Traceback (most recent call last):\n",
      "  File \"d:\\Anaconda\\envs\\TMenv\\lib\\site-packages\\flwr\\server\\superlink\\fleet\\vce\\vce_api.py\", line 112, in worker\n",
      "    out_mssg, updated_context = backend.process_message(message, context)\n",
      "  File \"d:\\Anaconda\\envs\\TMenv\\lib\\site-packages\\flwr\\server\\superlink\\fleet\\vce\\backend\\raybackend.py\", line 186, in process_message\n",
      "    self.pool.add_actor_back_to_pool(future)\n",
      "UnboundLocalError: local variable 'future' referenced before assignment\n",
      "\n",
      "\u001b[92mINFO 2025-07-12 23:24:12,422\u001b[0m:      aggregate_evaluate: received 0 results and 2 failures\n",
      "\u001b[92mINFO 2025-07-12 23:24:12,423\u001b[0m:      \n",
      "\u001b[92mINFO 2025-07-12 23:24:12,424\u001b[0m:      [ROUND 13]\n",
      "\u001b[92mINFO 2025-07-12 23:24:12,425\u001b[0m:      configure_fit: strategy sampled 2 clients (out of 2)\n",
      "\u001b[91mERROR 2025-07-12 23:24:12,498\u001b[0m:     An exception was raised when processing a message by RayBackend\n",
      "\u001b[91mERROR 2025-07-12 23:24:12,499\u001b[0m:     local variable 'future' referenced before assignment\n",
      "\u001b[91mERROR 2025-07-12 23:24:12,500\u001b[0m:     Traceback (most recent call last):\n",
      "  File \"d:\\Anaconda\\envs\\TMenv\\lib\\site-packages\\flwr\\server\\superlink\\fleet\\vce\\backend\\raybackend.py\", line 166, in process_message\n",
      "    future = self.pool.submit(\n",
      "  File \"d:\\Anaconda\\envs\\TMenv\\lib\\site-packages\\flwr\\simulation\\ray_transport\\ray_actor.py\", line 460, in submit\n",
      "    actor = self.pool.pop()\n",
      "IndexError: pop from empty list\n",
      "\n",
      "During handling of the above exception, another exception occurred:\n",
      "\n",
      "Traceback (most recent call last):\n",
      "  File \"d:\\Anaconda\\envs\\TMenv\\lib\\site-packages\\flwr\\server\\superlink\\fleet\\vce\\vce_api.py\", line 112, in worker\n",
      "    out_mssg, updated_context = backend.process_message(message, context)\n",
      "  File \"d:\\Anaconda\\envs\\TMenv\\lib\\site-packages\\flwr\\server\\superlink\\fleet\\vce\\backend\\raybackend.py\", line 186, in process_message\n",
      "    self.pool.add_actor_back_to_pool(future)\n",
      "UnboundLocalError: local variable 'future' referenced before assignment\n",
      "\n",
      "\u001b[91mERROR 2025-07-12 23:24:12,501\u001b[0m:     An exception was raised when processing a message by RayBackend\n",
      "\u001b[91mERROR 2025-07-12 23:24:12,501\u001b[0m:     local variable 'future' referenced before assignment\n",
      "\u001b[91mERROR 2025-07-12 23:24:12,503\u001b[0m:     Traceback (most recent call last):\n",
      "  File \"d:\\Anaconda\\envs\\TMenv\\lib\\site-packages\\flwr\\server\\superlink\\fleet\\vce\\backend\\raybackend.py\", line 166, in process_message\n",
      "    future = self.pool.submit(\n",
      "  File \"d:\\Anaconda\\envs\\TMenv\\lib\\site-packages\\flwr\\simulation\\ray_transport\\ray_actor.py\", line 460, in submit\n",
      "    actor = self.pool.pop()\n",
      "IndexError: pop from empty list\n",
      "\n",
      "During handling of the above exception, another exception occurred:\n",
      "\n",
      "Traceback (most recent call last):\n",
      "  File \"d:\\Anaconda\\envs\\TMenv\\lib\\site-packages\\flwr\\server\\superlink\\fleet\\vce\\vce_api.py\", line 112, in worker\n",
      "    out_mssg, updated_context = backend.process_message(message, context)\n",
      "  File \"d:\\Anaconda\\envs\\TMenv\\lib\\site-packages\\flwr\\server\\superlink\\fleet\\vce\\backend\\raybackend.py\", line 186, in process_message\n",
      "    self.pool.add_actor_back_to_pool(future)\n",
      "UnboundLocalError: local variable 'future' referenced before assignment\n",
      "\n",
      "\u001b[92mINFO 2025-07-12 23:24:12,530\u001b[0m:      aggregate_fit: received 0 results and 2 failures\n",
      "\u001b[92mINFO 2025-07-12 23:24:12,532\u001b[0m:      configure_evaluate: strategy sampled 2 clients (out of 2)\n",
      "\u001b[91mERROR 2025-07-12 23:24:12,608\u001b[0m:     An exception was raised when processing a message by RayBackend\n",
      "\u001b[91mERROR 2025-07-12 23:24:12,609\u001b[0m:     local variable 'future' referenced before assignment\n",
      "\u001b[91mERROR 2025-07-12 23:24:12,610\u001b[0m:     Traceback (most recent call last):\n",
      "  File \"d:\\Anaconda\\envs\\TMenv\\lib\\site-packages\\flwr\\server\\superlink\\fleet\\vce\\backend\\raybackend.py\", line 166, in process_message\n",
      "    future = self.pool.submit(\n",
      "  File \"d:\\Anaconda\\envs\\TMenv\\lib\\site-packages\\flwr\\simulation\\ray_transport\\ray_actor.py\", line 460, in submit\n",
      "    actor = self.pool.pop()\n",
      "IndexError: pop from empty list\n",
      "\n",
      "During handling of the above exception, another exception occurred:\n",
      "\n",
      "Traceback (most recent call last):\n",
      "  File \"d:\\Anaconda\\envs\\TMenv\\lib\\site-packages\\flwr\\server\\superlink\\fleet\\vce\\vce_api.py\", line 112, in worker\n",
      "    out_mssg, updated_context = backend.process_message(message, context)\n",
      "  File \"d:\\Anaconda\\envs\\TMenv\\lib\\site-packages\\flwr\\server\\superlink\\fleet\\vce\\backend\\raybackend.py\", line 186, in process_message\n",
      "    self.pool.add_actor_back_to_pool(future)\n",
      "UnboundLocalError: local variable 'future' referenced before assignment\n",
      "\n",
      "\u001b[91mERROR 2025-07-12 23:24:12,610\u001b[0m:     An exception was raised when processing a message by RayBackend\n",
      "\u001b[91mERROR 2025-07-12 23:24:12,611\u001b[0m:     local variable 'future' referenced before assignment\n",
      "\u001b[91mERROR 2025-07-12 23:24:12,612\u001b[0m:     Traceback (most recent call last):\n",
      "  File \"d:\\Anaconda\\envs\\TMenv\\lib\\site-packages\\flwr\\server\\superlink\\fleet\\vce\\backend\\raybackend.py\", line 166, in process_message\n",
      "    future = self.pool.submit(\n",
      "  File \"d:\\Anaconda\\envs\\TMenv\\lib\\site-packages\\flwr\\simulation\\ray_transport\\ray_actor.py\", line 460, in submit\n",
      "    actor = self.pool.pop()\n",
      "IndexError: pop from empty list\n",
      "\n",
      "During handling of the above exception, another exception occurred:\n",
      "\n",
      "Traceback (most recent call last):\n",
      "  File \"d:\\Anaconda\\envs\\TMenv\\lib\\site-packages\\flwr\\server\\superlink\\fleet\\vce\\vce_api.py\", line 112, in worker\n",
      "    out_mssg, updated_context = backend.process_message(message, context)\n",
      "  File \"d:\\Anaconda\\envs\\TMenv\\lib\\site-packages\\flwr\\server\\superlink\\fleet\\vce\\backend\\raybackend.py\", line 186, in process_message\n",
      "    self.pool.add_actor_back_to_pool(future)\n",
      "UnboundLocalError: local variable 'future' referenced before assignment\n",
      "\n",
      "\u001b[92mINFO 2025-07-12 23:24:12,639\u001b[0m:      aggregate_evaluate: received 0 results and 2 failures\n",
      "\u001b[92mINFO 2025-07-12 23:24:12,640\u001b[0m:      \n",
      "\u001b[92mINFO 2025-07-12 23:24:12,641\u001b[0m:      [ROUND 14]\n",
      "\u001b[92mINFO 2025-07-12 23:24:12,642\u001b[0m:      configure_fit: strategy sampled 2 clients (out of 2)\n",
      "\u001b[91mERROR 2025-07-12 23:24:12,717\u001b[0m:     An exception was raised when processing a message by RayBackend\n",
      "\u001b[91mERROR 2025-07-12 23:24:12,718\u001b[0m:     local variable 'future' referenced before assignment\n",
      "\u001b[91mERROR 2025-07-12 23:24:12,719\u001b[0m:     Traceback (most recent call last):\n",
      "  File \"d:\\Anaconda\\envs\\TMenv\\lib\\site-packages\\flwr\\server\\superlink\\fleet\\vce\\backend\\raybackend.py\", line 166, in process_message\n",
      "    future = self.pool.submit(\n",
      "  File \"d:\\Anaconda\\envs\\TMenv\\lib\\site-packages\\flwr\\simulation\\ray_transport\\ray_actor.py\", line 460, in submit\n",
      "    actor = self.pool.pop()\n",
      "IndexError: pop from empty list\n",
      "\n",
      "During handling of the above exception, another exception occurred:\n",
      "\n",
      "Traceback (most recent call last):\n",
      "  File \"d:\\Anaconda\\envs\\TMenv\\lib\\site-packages\\flwr\\server\\superlink\\fleet\\vce\\vce_api.py\", line 112, in worker\n",
      "    out_mssg, updated_context = backend.process_message(message, context)\n",
      "  File \"d:\\Anaconda\\envs\\TMenv\\lib\\site-packages\\flwr\\server\\superlink\\fleet\\vce\\backend\\raybackend.py\", line 186, in process_message\n",
      "    self.pool.add_actor_back_to_pool(future)\n",
      "UnboundLocalError: local variable 'future' referenced before assignment\n",
      "\n",
      "\u001b[91mERROR 2025-07-12 23:24:12,720\u001b[0m:     An exception was raised when processing a message by RayBackend\n",
      "\u001b[91mERROR 2025-07-12 23:24:12,720\u001b[0m:     local variable 'future' referenced before assignment\n",
      "\u001b[91mERROR 2025-07-12 23:24:12,721\u001b[0m:     Traceback (most recent call last):\n",
      "  File \"d:\\Anaconda\\envs\\TMenv\\lib\\site-packages\\flwr\\server\\superlink\\fleet\\vce\\backend\\raybackend.py\", line 166, in process_message\n",
      "    future = self.pool.submit(\n",
      "  File \"d:\\Anaconda\\envs\\TMenv\\lib\\site-packages\\flwr\\simulation\\ray_transport\\ray_actor.py\", line 460, in submit\n",
      "    actor = self.pool.pop()\n",
      "IndexError: pop from empty list\n",
      "\n",
      "During handling of the above exception, another exception occurred:\n",
      "\n",
      "Traceback (most recent call last):\n",
      "  File \"d:\\Anaconda\\envs\\TMenv\\lib\\site-packages\\flwr\\server\\superlink\\fleet\\vce\\vce_api.py\", line 112, in worker\n",
      "    out_mssg, updated_context = backend.process_message(message, context)\n",
      "  File \"d:\\Anaconda\\envs\\TMenv\\lib\\site-packages\\flwr\\server\\superlink\\fleet\\vce\\backend\\raybackend.py\", line 186, in process_message\n",
      "    self.pool.add_actor_back_to_pool(future)\n",
      "UnboundLocalError: local variable 'future' referenced before assignment\n",
      "\n",
      "\u001b[92mINFO 2025-07-12 23:24:12,748\u001b[0m:      aggregate_fit: received 0 results and 2 failures\n",
      "\u001b[92mINFO 2025-07-12 23:24:12,749\u001b[0m:      configure_evaluate: strategy sampled 2 clients (out of 2)\n",
      "\u001b[91mERROR 2025-07-12 23:24:12,824\u001b[0m:     An exception was raised when processing a message by RayBackend\n",
      "\u001b[91mERROR 2025-07-12 23:24:12,825\u001b[0m:     local variable 'future' referenced before assignment\n",
      "\u001b[91mERROR 2025-07-12 23:24:12,825\u001b[0m:     Traceback (most recent call last):\n",
      "  File \"d:\\Anaconda\\envs\\TMenv\\lib\\site-packages\\flwr\\server\\superlink\\fleet\\vce\\backend\\raybackend.py\", line 166, in process_message\n",
      "    future = self.pool.submit(\n",
      "  File \"d:\\Anaconda\\envs\\TMenv\\lib\\site-packages\\flwr\\simulation\\ray_transport\\ray_actor.py\", line 460, in submit\n",
      "    actor = self.pool.pop()\n",
      "IndexError: pop from empty list\n",
      "\n",
      "During handling of the above exception, another exception occurred:\n",
      "\n",
      "Traceback (most recent call last):\n",
      "  File \"d:\\Anaconda\\envs\\TMenv\\lib\\site-packages\\flwr\\server\\superlink\\fleet\\vce\\vce_api.py\", line 112, in worker\n",
      "    out_mssg, updated_context = backend.process_message(message, context)\n",
      "  File \"d:\\Anaconda\\envs\\TMenv\\lib\\site-packages\\flwr\\server\\superlink\\fleet\\vce\\backend\\raybackend.py\", line 186, in process_message\n",
      "    self.pool.add_actor_back_to_pool(future)\n",
      "UnboundLocalError: local variable 'future' referenced before assignment\n",
      "\n",
      "\u001b[91mERROR 2025-07-12 23:24:12,826\u001b[0m:     An exception was raised when processing a message by RayBackend\n",
      "\u001b[91mERROR 2025-07-12 23:24:12,826\u001b[0m:     local variable 'future' referenced before assignment\n",
      "\u001b[91mERROR 2025-07-12 23:24:12,828\u001b[0m:     Traceback (most recent call last):\n",
      "  File \"d:\\Anaconda\\envs\\TMenv\\lib\\site-packages\\flwr\\server\\superlink\\fleet\\vce\\backend\\raybackend.py\", line 166, in process_message\n",
      "    future = self.pool.submit(\n",
      "  File \"d:\\Anaconda\\envs\\TMenv\\lib\\site-packages\\flwr\\simulation\\ray_transport\\ray_actor.py\", line 460, in submit\n",
      "    actor = self.pool.pop()\n",
      "IndexError: pop from empty list\n",
      "\n",
      "During handling of the above exception, another exception occurred:\n",
      "\n",
      "Traceback (most recent call last):\n",
      "  File \"d:\\Anaconda\\envs\\TMenv\\lib\\site-packages\\flwr\\server\\superlink\\fleet\\vce\\vce_api.py\", line 112, in worker\n",
      "    out_mssg, updated_context = backend.process_message(message, context)\n",
      "  File \"d:\\Anaconda\\envs\\TMenv\\lib\\site-packages\\flwr\\server\\superlink\\fleet\\vce\\backend\\raybackend.py\", line 186, in process_message\n",
      "    self.pool.add_actor_back_to_pool(future)\n",
      "UnboundLocalError: local variable 'future' referenced before assignment\n",
      "\n",
      "\u001b[92mINFO 2025-07-12 23:24:12,856\u001b[0m:      aggregate_evaluate: received 0 results and 2 failures\n",
      "\u001b[92mINFO 2025-07-12 23:24:12,857\u001b[0m:      \n",
      "\u001b[92mINFO 2025-07-12 23:24:12,858\u001b[0m:      [ROUND 15]\n",
      "\u001b[92mINFO 2025-07-12 23:24:12,858\u001b[0m:      configure_fit: strategy sampled 2 clients (out of 2)\n",
      "\u001b[91mERROR 2025-07-12 23:24:12,933\u001b[0m:     An exception was raised when processing a message by RayBackend\n",
      "\u001b[91mERROR 2025-07-12 23:24:12,934\u001b[0m:     local variable 'future' referenced before assignment\n",
      "\u001b[91mERROR 2025-07-12 23:24:12,935\u001b[0m:     Traceback (most recent call last):\n",
      "  File \"d:\\Anaconda\\envs\\TMenv\\lib\\site-packages\\flwr\\server\\superlink\\fleet\\vce\\backend\\raybackend.py\", line 166, in process_message\n",
      "    future = self.pool.submit(\n",
      "  File \"d:\\Anaconda\\envs\\TMenv\\lib\\site-packages\\flwr\\simulation\\ray_transport\\ray_actor.py\", line 460, in submit\n",
      "    actor = self.pool.pop()\n",
      "IndexError: pop from empty list\n",
      "\n",
      "During handling of the above exception, another exception occurred:\n",
      "\n",
      "Traceback (most recent call last):\n",
      "  File \"d:\\Anaconda\\envs\\TMenv\\lib\\site-packages\\flwr\\server\\superlink\\fleet\\vce\\vce_api.py\", line 112, in worker\n",
      "    out_mssg, updated_context = backend.process_message(message, context)\n",
      "  File \"d:\\Anaconda\\envs\\TMenv\\lib\\site-packages\\flwr\\server\\superlink\\fleet\\vce\\backend\\raybackend.py\", line 186, in process_message\n",
      "    self.pool.add_actor_back_to_pool(future)\n",
      "UnboundLocalError: local variable 'future' referenced before assignment\n",
      "\n",
      "\u001b[91mERROR 2025-07-12 23:24:12,936\u001b[0m:     An exception was raised when processing a message by RayBackend\n",
      "\u001b[91mERROR 2025-07-12 23:24:12,936\u001b[0m:     local variable 'future' referenced before assignment\n",
      "\u001b[91mERROR 2025-07-12 23:24:12,937\u001b[0m:     Traceback (most recent call last):\n",
      "  File \"d:\\Anaconda\\envs\\TMenv\\lib\\site-packages\\flwr\\server\\superlink\\fleet\\vce\\backend\\raybackend.py\", line 166, in process_message\n",
      "    future = self.pool.submit(\n",
      "  File \"d:\\Anaconda\\envs\\TMenv\\lib\\site-packages\\flwr\\simulation\\ray_transport\\ray_actor.py\", line 460, in submit\n",
      "    actor = self.pool.pop()\n",
      "IndexError: pop from empty list\n",
      "\n",
      "During handling of the above exception, another exception occurred:\n",
      "\n",
      "Traceback (most recent call last):\n",
      "  File \"d:\\Anaconda\\envs\\TMenv\\lib\\site-packages\\flwr\\server\\superlink\\fleet\\vce\\vce_api.py\", line 112, in worker\n",
      "    out_mssg, updated_context = backend.process_message(message, context)\n",
      "  File \"d:\\Anaconda\\envs\\TMenv\\lib\\site-packages\\flwr\\server\\superlink\\fleet\\vce\\backend\\raybackend.py\", line 186, in process_message\n",
      "    self.pool.add_actor_back_to_pool(future)\n",
      "UnboundLocalError: local variable 'future' referenced before assignment\n",
      "\n",
      "\u001b[92mINFO 2025-07-12 23:24:12,964\u001b[0m:      aggregate_fit: received 0 results and 2 failures\n",
      "\u001b[92mINFO 2025-07-12 23:24:12,965\u001b[0m:      configure_evaluate: strategy sampled 2 clients (out of 2)\n",
      "\u001b[91mERROR 2025-07-12 23:24:13,041\u001b[0m:     An exception was raised when processing a message by RayBackend\n",
      "\u001b[91mERROR 2025-07-12 23:24:13,042\u001b[0m:     local variable 'future' referenced before assignment\n",
      "\u001b[91mERROR 2025-07-12 23:24:13,043\u001b[0m:     Traceback (most recent call last):\n",
      "  File \"d:\\Anaconda\\envs\\TMenv\\lib\\site-packages\\flwr\\server\\superlink\\fleet\\vce\\backend\\raybackend.py\", line 166, in process_message\n",
      "    future = self.pool.submit(\n",
      "  File \"d:\\Anaconda\\envs\\TMenv\\lib\\site-packages\\flwr\\simulation\\ray_transport\\ray_actor.py\", line 460, in submit\n",
      "    actor = self.pool.pop()\n",
      "IndexError: pop from empty list\n",
      "\n",
      "During handling of the above exception, another exception occurred:\n",
      "\n",
      "Traceback (most recent call last):\n",
      "  File \"d:\\Anaconda\\envs\\TMenv\\lib\\site-packages\\flwr\\server\\superlink\\fleet\\vce\\vce_api.py\", line 112, in worker\n",
      "    out_mssg, updated_context = backend.process_message(message, context)\n",
      "  File \"d:\\Anaconda\\envs\\TMenv\\lib\\site-packages\\flwr\\server\\superlink\\fleet\\vce\\backend\\raybackend.py\", line 186, in process_message\n",
      "    self.pool.add_actor_back_to_pool(future)\n",
      "UnboundLocalError: local variable 'future' referenced before assignment\n",
      "\n",
      "\u001b[91mERROR 2025-07-12 23:24:13,043\u001b[0m:     An exception was raised when processing a message by RayBackend\n",
      "\u001b[91mERROR 2025-07-12 23:24:13,044\u001b[0m:     local variable 'future' referenced before assignment\n",
      "\u001b[91mERROR 2025-07-12 23:24:13,045\u001b[0m:     Traceback (most recent call last):\n",
      "  File \"d:\\Anaconda\\envs\\TMenv\\lib\\site-packages\\flwr\\server\\superlink\\fleet\\vce\\backend\\raybackend.py\", line 166, in process_message\n",
      "    future = self.pool.submit(\n",
      "  File \"d:\\Anaconda\\envs\\TMenv\\lib\\site-packages\\flwr\\simulation\\ray_transport\\ray_actor.py\", line 460, in submit\n",
      "    actor = self.pool.pop()\n",
      "IndexError: pop from empty list\n",
      "\n",
      "During handling of the above exception, another exception occurred:\n",
      "\n",
      "Traceback (most recent call last):\n",
      "  File \"d:\\Anaconda\\envs\\TMenv\\lib\\site-packages\\flwr\\server\\superlink\\fleet\\vce\\vce_api.py\", line 112, in worker\n",
      "    out_mssg, updated_context = backend.process_message(message, context)\n",
      "  File \"d:\\Anaconda\\envs\\TMenv\\lib\\site-packages\\flwr\\server\\superlink\\fleet\\vce\\backend\\raybackend.py\", line 186, in process_message\n",
      "    self.pool.add_actor_back_to_pool(future)\n",
      "UnboundLocalError: local variable 'future' referenced before assignment\n",
      "\n",
      "\u001b[92mINFO 2025-07-12 23:24:13,073\u001b[0m:      aggregate_evaluate: received 0 results and 2 failures\n",
      "\u001b[92mINFO 2025-07-12 23:24:13,073\u001b[0m:      \n",
      "\u001b[92mINFO 2025-07-12 23:24:13,074\u001b[0m:      [ROUND 16]\n",
      "\u001b[92mINFO 2025-07-12 23:24:13,075\u001b[0m:      configure_fit: strategy sampled 2 clients (out of 2)\n",
      "\u001b[91mERROR 2025-07-12 23:24:13,148\u001b[0m:     An exception was raised when processing a message by RayBackend\n",
      "\u001b[91mERROR 2025-07-12 23:24:13,149\u001b[0m:     local variable 'future' referenced before assignment\n",
      "\u001b[91mERROR 2025-07-12 23:24:13,150\u001b[0m:     Traceback (most recent call last):\n",
      "  File \"d:\\Anaconda\\envs\\TMenv\\lib\\site-packages\\flwr\\server\\superlink\\fleet\\vce\\backend\\raybackend.py\", line 166, in process_message\n",
      "    future = self.pool.submit(\n",
      "  File \"d:\\Anaconda\\envs\\TMenv\\lib\\site-packages\\flwr\\simulation\\ray_transport\\ray_actor.py\", line 460, in submit\n",
      "    actor = self.pool.pop()\n",
      "IndexError: pop from empty list\n",
      "\n",
      "During handling of the above exception, another exception occurred:\n",
      "\n",
      "Traceback (most recent call last):\n",
      "  File \"d:\\Anaconda\\envs\\TMenv\\lib\\site-packages\\flwr\\server\\superlink\\fleet\\vce\\vce_api.py\", line 112, in worker\n",
      "    out_mssg, updated_context = backend.process_message(message, context)\n",
      "  File \"d:\\Anaconda\\envs\\TMenv\\lib\\site-packages\\flwr\\server\\superlink\\fleet\\vce\\backend\\raybackend.py\", line 186, in process_message\n",
      "    self.pool.add_actor_back_to_pool(future)\n",
      "UnboundLocalError: local variable 'future' referenced before assignment\n",
      "\n",
      "\u001b[91mERROR 2025-07-12 23:24:13,150\u001b[0m:     An exception was raised when processing a message by RayBackend\n",
      "\u001b[91mERROR 2025-07-12 23:24:13,151\u001b[0m:     local variable 'future' referenced before assignment\n",
      "\u001b[91mERROR 2025-07-12 23:24:13,152\u001b[0m:     Traceback (most recent call last):\n",
      "  File \"d:\\Anaconda\\envs\\TMenv\\lib\\site-packages\\flwr\\server\\superlink\\fleet\\vce\\backend\\raybackend.py\", line 166, in process_message\n",
      "    future = self.pool.submit(\n",
      "  File \"d:\\Anaconda\\envs\\TMenv\\lib\\site-packages\\flwr\\simulation\\ray_transport\\ray_actor.py\", line 460, in submit\n",
      "    actor = self.pool.pop()\n",
      "IndexError: pop from empty list\n",
      "\n",
      "During handling of the above exception, another exception occurred:\n",
      "\n",
      "Traceback (most recent call last):\n",
      "  File \"d:\\Anaconda\\envs\\TMenv\\lib\\site-packages\\flwr\\server\\superlink\\fleet\\vce\\vce_api.py\", line 112, in worker\n",
      "    out_mssg, updated_context = backend.process_message(message, context)\n",
      "  File \"d:\\Anaconda\\envs\\TMenv\\lib\\site-packages\\flwr\\server\\superlink\\fleet\\vce\\backend\\raybackend.py\", line 186, in process_message\n",
      "    self.pool.add_actor_back_to_pool(future)\n",
      "UnboundLocalError: local variable 'future' referenced before assignment\n",
      "\n",
      "\u001b[92mINFO 2025-07-12 23:24:13,179\u001b[0m:      aggregate_fit: received 0 results and 2 failures\n",
      "\u001b[92mINFO 2025-07-12 23:24:13,180\u001b[0m:      configure_evaluate: strategy sampled 2 clients (out of 2)\n",
      "\u001b[91mERROR 2025-07-12 23:24:13,258\u001b[0m:     An exception was raised when processing a message by RayBackend\n",
      "\u001b[91mERROR 2025-07-12 23:24:13,259\u001b[0m:     local variable 'future' referenced before assignment\n",
      "\u001b[91mERROR 2025-07-12 23:24:13,260\u001b[0m:     Traceback (most recent call last):\n",
      "  File \"d:\\Anaconda\\envs\\TMenv\\lib\\site-packages\\flwr\\server\\superlink\\fleet\\vce\\backend\\raybackend.py\", line 166, in process_message\n",
      "    future = self.pool.submit(\n",
      "  File \"d:\\Anaconda\\envs\\TMenv\\lib\\site-packages\\flwr\\simulation\\ray_transport\\ray_actor.py\", line 460, in submit\n",
      "    actor = self.pool.pop()\n",
      "IndexError: pop from empty list\n",
      "\n",
      "During handling of the above exception, another exception occurred:\n",
      "\n",
      "Traceback (most recent call last):\n",
      "  File \"d:\\Anaconda\\envs\\TMenv\\lib\\site-packages\\flwr\\server\\superlink\\fleet\\vce\\vce_api.py\", line 112, in worker\n",
      "    out_mssg, updated_context = backend.process_message(message, context)\n",
      "  File \"d:\\Anaconda\\envs\\TMenv\\lib\\site-packages\\flwr\\server\\superlink\\fleet\\vce\\backend\\raybackend.py\", line 186, in process_message\n",
      "    self.pool.add_actor_back_to_pool(future)\n",
      "UnboundLocalError: local variable 'future' referenced before assignment\n",
      "\n",
      "\u001b[91mERROR 2025-07-12 23:24:13,260\u001b[0m:     An exception was raised when processing a message by RayBackend\n",
      "\u001b[91mERROR 2025-07-12 23:24:13,261\u001b[0m:     local variable 'future' referenced before assignment\n",
      "\u001b[91mERROR 2025-07-12 23:24:13,262\u001b[0m:     Traceback (most recent call last):\n",
      "  File \"d:\\Anaconda\\envs\\TMenv\\lib\\site-packages\\flwr\\server\\superlink\\fleet\\vce\\backend\\raybackend.py\", line 166, in process_message\n",
      "    future = self.pool.submit(\n",
      "  File \"d:\\Anaconda\\envs\\TMenv\\lib\\site-packages\\flwr\\simulation\\ray_transport\\ray_actor.py\", line 460, in submit\n",
      "    actor = self.pool.pop()\n",
      "IndexError: pop from empty list\n",
      "\n",
      "During handling of the above exception, another exception occurred:\n",
      "\n",
      "Traceback (most recent call last):\n",
      "  File \"d:\\Anaconda\\envs\\TMenv\\lib\\site-packages\\flwr\\server\\superlink\\fleet\\vce\\vce_api.py\", line 112, in worker\n",
      "    out_mssg, updated_context = backend.process_message(message, context)\n",
      "  File \"d:\\Anaconda\\envs\\TMenv\\lib\\site-packages\\flwr\\server\\superlink\\fleet\\vce\\backend\\raybackend.py\", line 186, in process_message\n",
      "    self.pool.add_actor_back_to_pool(future)\n",
      "UnboundLocalError: local variable 'future' referenced before assignment\n",
      "\n",
      "\u001b[92mINFO 2025-07-12 23:24:13,289\u001b[0m:      aggregate_evaluate: received 0 results and 2 failures\n",
      "\u001b[92mINFO 2025-07-12 23:24:13,290\u001b[0m:      \n",
      "\u001b[92mINFO 2025-07-12 23:24:13,291\u001b[0m:      [ROUND 17]\n",
      "\u001b[92mINFO 2025-07-12 23:24:13,291\u001b[0m:      configure_fit: strategy sampled 2 clients (out of 2)\n",
      "\u001b[91mERROR 2025-07-12 23:24:13,366\u001b[0m:     An exception was raised when processing a message by RayBackend\n",
      "\u001b[91mERROR 2025-07-12 23:24:13,367\u001b[0m:     local variable 'future' referenced before assignment\n",
      "\u001b[91mERROR 2025-07-12 23:24:13,369\u001b[0m:     Traceback (most recent call last):\n",
      "  File \"d:\\Anaconda\\envs\\TMenv\\lib\\site-packages\\flwr\\server\\superlink\\fleet\\vce\\backend\\raybackend.py\", line 166, in process_message\n",
      "    future = self.pool.submit(\n",
      "  File \"d:\\Anaconda\\envs\\TMenv\\lib\\site-packages\\flwr\\simulation\\ray_transport\\ray_actor.py\", line 460, in submit\n",
      "    actor = self.pool.pop()\n",
      "IndexError: pop from empty list\n",
      "\n",
      "During handling of the above exception, another exception occurred:\n",
      "\n",
      "Traceback (most recent call last):\n",
      "  File \"d:\\Anaconda\\envs\\TMenv\\lib\\site-packages\\flwr\\server\\superlink\\fleet\\vce\\vce_api.py\", line 112, in worker\n",
      "    out_mssg, updated_context = backend.process_message(message, context)\n",
      "  File \"d:\\Anaconda\\envs\\TMenv\\lib\\site-packages\\flwr\\server\\superlink\\fleet\\vce\\backend\\raybackend.py\", line 186, in process_message\n",
      "    self.pool.add_actor_back_to_pool(future)\n",
      "UnboundLocalError: local variable 'future' referenced before assignment\n",
      "\n",
      "\u001b[91mERROR 2025-07-12 23:24:13,370\u001b[0m:     An exception was raised when processing a message by RayBackend\n",
      "\u001b[91mERROR 2025-07-12 23:24:13,371\u001b[0m:     local variable 'future' referenced before assignment\n",
      "\u001b[91mERROR 2025-07-12 23:24:13,373\u001b[0m:     Traceback (most recent call last):\n",
      "  File \"d:\\Anaconda\\envs\\TMenv\\lib\\site-packages\\flwr\\server\\superlink\\fleet\\vce\\backend\\raybackend.py\", line 166, in process_message\n",
      "    future = self.pool.submit(\n",
      "  File \"d:\\Anaconda\\envs\\TMenv\\lib\\site-packages\\flwr\\simulation\\ray_transport\\ray_actor.py\", line 460, in submit\n",
      "    actor = self.pool.pop()\n",
      "IndexError: pop from empty list\n",
      "\n",
      "During handling of the above exception, another exception occurred:\n",
      "\n",
      "Traceback (most recent call last):\n",
      "  File \"d:\\Anaconda\\envs\\TMenv\\lib\\site-packages\\flwr\\server\\superlink\\fleet\\vce\\vce_api.py\", line 112, in worker\n",
      "    out_mssg, updated_context = backend.process_message(message, context)\n",
      "  File \"d:\\Anaconda\\envs\\TMenv\\lib\\site-packages\\flwr\\server\\superlink\\fleet\\vce\\backend\\raybackend.py\", line 186, in process_message\n",
      "    self.pool.add_actor_back_to_pool(future)\n",
      "UnboundLocalError: local variable 'future' referenced before assignment\n",
      "\n",
      "\u001b[92mINFO 2025-07-12 23:24:13,396\u001b[0m:      aggregate_fit: received 0 results and 2 failures\n",
      "\u001b[92mINFO 2025-07-12 23:24:13,397\u001b[0m:      configure_evaluate: strategy sampled 2 clients (out of 2)\n",
      "\u001b[91mERROR 2025-07-12 23:24:13,473\u001b[0m:     An exception was raised when processing a message by RayBackend\n",
      "\u001b[91mERROR 2025-07-12 23:24:13,474\u001b[0m:     local variable 'future' referenced before assignment\n",
      "\u001b[91mERROR 2025-07-12 23:24:13,475\u001b[0m:     Traceback (most recent call last):\n",
      "  File \"d:\\Anaconda\\envs\\TMenv\\lib\\site-packages\\flwr\\server\\superlink\\fleet\\vce\\backend\\raybackend.py\", line 166, in process_message\n",
      "    future = self.pool.submit(\n",
      "  File \"d:\\Anaconda\\envs\\TMenv\\lib\\site-packages\\flwr\\simulation\\ray_transport\\ray_actor.py\", line 460, in submit\n",
      "    actor = self.pool.pop()\n",
      "IndexError: pop from empty list\n",
      "\n",
      "During handling of the above exception, another exception occurred:\n",
      "\n",
      "Traceback (most recent call last):\n",
      "  File \"d:\\Anaconda\\envs\\TMenv\\lib\\site-packages\\flwr\\server\\superlink\\fleet\\vce\\vce_api.py\", line 112, in worker\n",
      "    out_mssg, updated_context = backend.process_message(message, context)\n",
      "  File \"d:\\Anaconda\\envs\\TMenv\\lib\\site-packages\\flwr\\server\\superlink\\fleet\\vce\\backend\\raybackend.py\", line 186, in process_message\n",
      "    self.pool.add_actor_back_to_pool(future)\n",
      "UnboundLocalError: local variable 'future' referenced before assignment\n",
      "\n",
      "\u001b[91mERROR 2025-07-12 23:24:13,476\u001b[0m:     An exception was raised when processing a message by RayBackend\n",
      "\u001b[91mERROR 2025-07-12 23:24:13,477\u001b[0m:     local variable 'future' referenced before assignment\n",
      "\u001b[91mERROR 2025-07-12 23:24:13,478\u001b[0m:     Traceback (most recent call last):\n",
      "  File \"d:\\Anaconda\\envs\\TMenv\\lib\\site-packages\\flwr\\server\\superlink\\fleet\\vce\\backend\\raybackend.py\", line 166, in process_message\n",
      "    future = self.pool.submit(\n",
      "  File \"d:\\Anaconda\\envs\\TMenv\\lib\\site-packages\\flwr\\simulation\\ray_transport\\ray_actor.py\", line 460, in submit\n",
      "    actor = self.pool.pop()\n",
      "IndexError: pop from empty list\n",
      "\n",
      "During handling of the above exception, another exception occurred:\n",
      "\n",
      "Traceback (most recent call last):\n",
      "  File \"d:\\Anaconda\\envs\\TMenv\\lib\\site-packages\\flwr\\server\\superlink\\fleet\\vce\\vce_api.py\", line 112, in worker\n",
      "    out_mssg, updated_context = backend.process_message(message, context)\n",
      "  File \"d:\\Anaconda\\envs\\TMenv\\lib\\site-packages\\flwr\\server\\superlink\\fleet\\vce\\backend\\raybackend.py\", line 186, in process_message\n",
      "    self.pool.add_actor_back_to_pool(future)\n",
      "UnboundLocalError: local variable 'future' referenced before assignment\n",
      "\n",
      "\u001b[92mINFO 2025-07-12 23:24:13,504\u001b[0m:      aggregate_evaluate: received 0 results and 2 failures\n",
      "\u001b[92mINFO 2025-07-12 23:24:13,505\u001b[0m:      \n",
      "\u001b[92mINFO 2025-07-12 23:24:13,506\u001b[0m:      [ROUND 18]\n",
      "\u001b[92mINFO 2025-07-12 23:24:13,507\u001b[0m:      configure_fit: strategy sampled 2 clients (out of 2)\n",
      "\u001b[91mERROR 2025-07-12 23:24:13,581\u001b[0m:     An exception was raised when processing a message by RayBackend\n",
      "\u001b[91mERROR 2025-07-12 23:24:13,582\u001b[0m:     local variable 'future' referenced before assignment\n",
      "\u001b[91mERROR 2025-07-12 23:24:13,583\u001b[0m:     Traceback (most recent call last):\n",
      "  File \"d:\\Anaconda\\envs\\TMenv\\lib\\site-packages\\flwr\\server\\superlink\\fleet\\vce\\backend\\raybackend.py\", line 166, in process_message\n",
      "    future = self.pool.submit(\n",
      "  File \"d:\\Anaconda\\envs\\TMenv\\lib\\site-packages\\flwr\\simulation\\ray_transport\\ray_actor.py\", line 460, in submit\n",
      "    actor = self.pool.pop()\n",
      "IndexError: pop from empty list\n",
      "\n",
      "During handling of the above exception, another exception occurred:\n",
      "\n",
      "Traceback (most recent call last):\n",
      "  File \"d:\\Anaconda\\envs\\TMenv\\lib\\site-packages\\flwr\\server\\superlink\\fleet\\vce\\vce_api.py\", line 112, in worker\n",
      "    out_mssg, updated_context = backend.process_message(message, context)\n",
      "  File \"d:\\Anaconda\\envs\\TMenv\\lib\\site-packages\\flwr\\server\\superlink\\fleet\\vce\\backend\\raybackend.py\", line 186, in process_message\n",
      "    self.pool.add_actor_back_to_pool(future)\n",
      "UnboundLocalError: local variable 'future' referenced before assignment\n",
      "\n",
      "\u001b[91mERROR 2025-07-12 23:24:13,584\u001b[0m:     An exception was raised when processing a message by RayBackend\n",
      "\u001b[91mERROR 2025-07-12 23:24:13,584\u001b[0m:     local variable 'future' referenced before assignment\n",
      "\u001b[91mERROR 2025-07-12 23:24:13,585\u001b[0m:     Traceback (most recent call last):\n",
      "  File \"d:\\Anaconda\\envs\\TMenv\\lib\\site-packages\\flwr\\server\\superlink\\fleet\\vce\\backend\\raybackend.py\", line 166, in process_message\n",
      "    future = self.pool.submit(\n",
      "  File \"d:\\Anaconda\\envs\\TMenv\\lib\\site-packages\\flwr\\simulation\\ray_transport\\ray_actor.py\", line 460, in submit\n",
      "    actor = self.pool.pop()\n",
      "IndexError: pop from empty list\n",
      "\n",
      "During handling of the above exception, another exception occurred:\n",
      "\n",
      "Traceback (most recent call last):\n",
      "  File \"d:\\Anaconda\\envs\\TMenv\\lib\\site-packages\\flwr\\server\\superlink\\fleet\\vce\\vce_api.py\", line 112, in worker\n",
      "    out_mssg, updated_context = backend.process_message(message, context)\n",
      "  File \"d:\\Anaconda\\envs\\TMenv\\lib\\site-packages\\flwr\\server\\superlink\\fleet\\vce\\backend\\raybackend.py\", line 186, in process_message\n",
      "    self.pool.add_actor_back_to_pool(future)\n",
      "UnboundLocalError: local variable 'future' referenced before assignment\n",
      "\n",
      "\u001b[92mINFO 2025-07-12 23:24:13,612\u001b[0m:      aggregate_fit: received 0 results and 2 failures\n",
      "\u001b[92mINFO 2025-07-12 23:24:13,613\u001b[0m:      configure_evaluate: strategy sampled 2 clients (out of 2)\n",
      "\u001b[91mERROR 2025-07-12 23:24:13,689\u001b[0m:     An exception was raised when processing a message by RayBackend\n",
      "\u001b[91mERROR 2025-07-12 23:24:13,690\u001b[0m:     local variable 'future' referenced before assignment\n",
      "\u001b[91mERROR 2025-07-12 23:24:13,691\u001b[0m:     Traceback (most recent call last):\n",
      "  File \"d:\\Anaconda\\envs\\TMenv\\lib\\site-packages\\flwr\\server\\superlink\\fleet\\vce\\backend\\raybackend.py\", line 166, in process_message\n",
      "    future = self.pool.submit(\n",
      "  File \"d:\\Anaconda\\envs\\TMenv\\lib\\site-packages\\flwr\\simulation\\ray_transport\\ray_actor.py\", line 460, in submit\n",
      "    actor = self.pool.pop()\n",
      "IndexError: pop from empty list\n",
      "\n",
      "During handling of the above exception, another exception occurred:\n",
      "\n",
      "Traceback (most recent call last):\n",
      "  File \"d:\\Anaconda\\envs\\TMenv\\lib\\site-packages\\flwr\\server\\superlink\\fleet\\vce\\vce_api.py\", line 112, in worker\n",
      "    out_mssg, updated_context = backend.process_message(message, context)\n",
      "  File \"d:\\Anaconda\\envs\\TMenv\\lib\\site-packages\\flwr\\server\\superlink\\fleet\\vce\\backend\\raybackend.py\", line 186, in process_message\n",
      "    self.pool.add_actor_back_to_pool(future)\n",
      "UnboundLocalError: local variable 'future' referenced before assignment\n",
      "\n",
      "\u001b[91mERROR 2025-07-12 23:24:13,692\u001b[0m:     An exception was raised when processing a message by RayBackend\n",
      "\u001b[91mERROR 2025-07-12 23:24:13,692\u001b[0m:     local variable 'future' referenced before assignment\n",
      "\u001b[91mERROR 2025-07-12 23:24:13,693\u001b[0m:     Traceback (most recent call last):\n",
      "  File \"d:\\Anaconda\\envs\\TMenv\\lib\\site-packages\\flwr\\server\\superlink\\fleet\\vce\\backend\\raybackend.py\", line 166, in process_message\n",
      "    future = self.pool.submit(\n",
      "  File \"d:\\Anaconda\\envs\\TMenv\\lib\\site-packages\\flwr\\simulation\\ray_transport\\ray_actor.py\", line 460, in submit\n",
      "    actor = self.pool.pop()\n",
      "IndexError: pop from empty list\n",
      "\n",
      "During handling of the above exception, another exception occurred:\n",
      "\n",
      "Traceback (most recent call last):\n",
      "  File \"d:\\Anaconda\\envs\\TMenv\\lib\\site-packages\\flwr\\server\\superlink\\fleet\\vce\\vce_api.py\", line 112, in worker\n",
      "    out_mssg, updated_context = backend.process_message(message, context)\n",
      "  File \"d:\\Anaconda\\envs\\TMenv\\lib\\site-packages\\flwr\\server\\superlink\\fleet\\vce\\backend\\raybackend.py\", line 186, in process_message\n",
      "    self.pool.add_actor_back_to_pool(future)\n",
      "UnboundLocalError: local variable 'future' referenced before assignment\n",
      "\n",
      "\u001b[92mINFO 2025-07-12 23:24:13,721\u001b[0m:      aggregate_evaluate: received 0 results and 2 failures\n",
      "\u001b[92mINFO 2025-07-12 23:24:13,722\u001b[0m:      \n",
      "\u001b[92mINFO 2025-07-12 23:24:13,722\u001b[0m:      [ROUND 19]\n",
      "\u001b[92mINFO 2025-07-12 23:24:13,723\u001b[0m:      configure_fit: strategy sampled 2 clients (out of 2)\n",
      "\u001b[91mERROR 2025-07-12 23:24:13,797\u001b[0m:     An exception was raised when processing a message by RayBackend\n",
      "\u001b[91mERROR 2025-07-12 23:24:13,798\u001b[0m:     local variable 'future' referenced before assignment\n",
      "\u001b[91mERROR 2025-07-12 23:24:13,799\u001b[0m:     Traceback (most recent call last):\n",
      "  File \"d:\\Anaconda\\envs\\TMenv\\lib\\site-packages\\flwr\\server\\superlink\\fleet\\vce\\backend\\raybackend.py\", line 166, in process_message\n",
      "    future = self.pool.submit(\n",
      "  File \"d:\\Anaconda\\envs\\TMenv\\lib\\site-packages\\flwr\\simulation\\ray_transport\\ray_actor.py\", line 460, in submit\n",
      "    actor = self.pool.pop()\n",
      "IndexError: pop from empty list\n",
      "\n",
      "During handling of the above exception, another exception occurred:\n",
      "\n",
      "Traceback (most recent call last):\n",
      "  File \"d:\\Anaconda\\envs\\TMenv\\lib\\site-packages\\flwr\\server\\superlink\\fleet\\vce\\vce_api.py\", line 112, in worker\n",
      "    out_mssg, updated_context = backend.process_message(message, context)\n",
      "  File \"d:\\Anaconda\\envs\\TMenv\\lib\\site-packages\\flwr\\server\\superlink\\fleet\\vce\\backend\\raybackend.py\", line 186, in process_message\n",
      "    self.pool.add_actor_back_to_pool(future)\n",
      "UnboundLocalError: local variable 'future' referenced before assignment\n",
      "\n",
      "\u001b[91mERROR 2025-07-12 23:24:13,800\u001b[0m:     An exception was raised when processing a message by RayBackend\n",
      "\u001b[91mERROR 2025-07-12 23:24:13,801\u001b[0m:     local variable 'future' referenced before assignment\n",
      "\u001b[91mERROR 2025-07-12 23:24:13,802\u001b[0m:     Traceback (most recent call last):\n",
      "  File \"d:\\Anaconda\\envs\\TMenv\\lib\\site-packages\\flwr\\server\\superlink\\fleet\\vce\\backend\\raybackend.py\", line 166, in process_message\n",
      "    future = self.pool.submit(\n",
      "  File \"d:\\Anaconda\\envs\\TMenv\\lib\\site-packages\\flwr\\simulation\\ray_transport\\ray_actor.py\", line 460, in submit\n",
      "    actor = self.pool.pop()\n",
      "IndexError: pop from empty list\n",
      "\n",
      "During handling of the above exception, another exception occurred:\n",
      "\n",
      "Traceback (most recent call last):\n",
      "  File \"d:\\Anaconda\\envs\\TMenv\\lib\\site-packages\\flwr\\server\\superlink\\fleet\\vce\\vce_api.py\", line 112, in worker\n",
      "    out_mssg, updated_context = backend.process_message(message, context)\n",
      "  File \"d:\\Anaconda\\envs\\TMenv\\lib\\site-packages\\flwr\\server\\superlink\\fleet\\vce\\backend\\raybackend.py\", line 186, in process_message\n",
      "    self.pool.add_actor_back_to_pool(future)\n",
      "UnboundLocalError: local variable 'future' referenced before assignment\n",
      "\n",
      "\u001b[92mINFO 2025-07-12 23:24:13,828\u001b[0m:      aggregate_fit: received 0 results and 2 failures\n",
      "\u001b[92mINFO 2025-07-12 23:24:13,830\u001b[0m:      configure_evaluate: strategy sampled 2 clients (out of 2)\n",
      "\u001b[91mERROR 2025-07-12 23:24:13,906\u001b[0m:     An exception was raised when processing a message by RayBackend\n",
      "\u001b[91mERROR 2025-07-12 23:24:13,907\u001b[0m:     local variable 'future' referenced before assignment\n",
      "\u001b[91mERROR 2025-07-12 23:24:13,907\u001b[0m:     Traceback (most recent call last):\n",
      "  File \"d:\\Anaconda\\envs\\TMenv\\lib\\site-packages\\flwr\\server\\superlink\\fleet\\vce\\backend\\raybackend.py\", line 166, in process_message\n",
      "    future = self.pool.submit(\n",
      "  File \"d:\\Anaconda\\envs\\TMenv\\lib\\site-packages\\flwr\\simulation\\ray_transport\\ray_actor.py\", line 460, in submit\n",
      "    actor = self.pool.pop()\n",
      "IndexError: pop from empty list\n",
      "\n",
      "During handling of the above exception, another exception occurred:\n",
      "\n",
      "Traceback (most recent call last):\n",
      "  File \"d:\\Anaconda\\envs\\TMenv\\lib\\site-packages\\flwr\\server\\superlink\\fleet\\vce\\vce_api.py\", line 112, in worker\n",
      "    out_mssg, updated_context = backend.process_message(message, context)\n",
      "  File \"d:\\Anaconda\\envs\\TMenv\\lib\\site-packages\\flwr\\server\\superlink\\fleet\\vce\\backend\\raybackend.py\", line 186, in process_message\n",
      "    self.pool.add_actor_back_to_pool(future)\n",
      "UnboundLocalError: local variable 'future' referenced before assignment\n",
      "\n",
      "\u001b[91mERROR 2025-07-12 23:24:13,908\u001b[0m:     An exception was raised when processing a message by RayBackend\n",
      "\u001b[91mERROR 2025-07-12 23:24:13,909\u001b[0m:     local variable 'future' referenced before assignment\n",
      "\u001b[91mERROR 2025-07-12 23:24:13,909\u001b[0m:     Traceback (most recent call last):\n",
      "  File \"d:\\Anaconda\\envs\\TMenv\\lib\\site-packages\\flwr\\server\\superlink\\fleet\\vce\\backend\\raybackend.py\", line 166, in process_message\n",
      "    future = self.pool.submit(\n",
      "  File \"d:\\Anaconda\\envs\\TMenv\\lib\\site-packages\\flwr\\simulation\\ray_transport\\ray_actor.py\", line 460, in submit\n",
      "    actor = self.pool.pop()\n",
      "IndexError: pop from empty list\n",
      "\n",
      "During handling of the above exception, another exception occurred:\n",
      "\n",
      "Traceback (most recent call last):\n",
      "  File \"d:\\Anaconda\\envs\\TMenv\\lib\\site-packages\\flwr\\server\\superlink\\fleet\\vce\\vce_api.py\", line 112, in worker\n",
      "    out_mssg, updated_context = backend.process_message(message, context)\n",
      "  File \"d:\\Anaconda\\envs\\TMenv\\lib\\site-packages\\flwr\\server\\superlink\\fleet\\vce\\backend\\raybackend.py\", line 186, in process_message\n",
      "    self.pool.add_actor_back_to_pool(future)\n",
      "UnboundLocalError: local variable 'future' referenced before assignment\n",
      "\n",
      "\u001b[92mINFO 2025-07-12 23:24:13,937\u001b[0m:      aggregate_evaluate: received 0 results and 2 failures\n",
      "\u001b[92mINFO 2025-07-12 23:24:13,938\u001b[0m:      \n",
      "\u001b[92mINFO 2025-07-12 23:24:13,938\u001b[0m:      [ROUND 20]\n",
      "\u001b[92mINFO 2025-07-12 23:24:13,939\u001b[0m:      configure_fit: strategy sampled 2 clients (out of 2)\n",
      "\u001b[91mERROR 2025-07-12 23:24:14,014\u001b[0m:     An exception was raised when processing a message by RayBackend\n",
      "\u001b[91mERROR 2025-07-12 23:24:14,015\u001b[0m:     local variable 'future' referenced before assignment\n",
      "\u001b[91mERROR 2025-07-12 23:24:14,016\u001b[0m:     Traceback (most recent call last):\n",
      "  File \"d:\\Anaconda\\envs\\TMenv\\lib\\site-packages\\flwr\\server\\superlink\\fleet\\vce\\backend\\raybackend.py\", line 166, in process_message\n",
      "    future = self.pool.submit(\n",
      "  File \"d:\\Anaconda\\envs\\TMenv\\lib\\site-packages\\flwr\\simulation\\ray_transport\\ray_actor.py\", line 460, in submit\n",
      "    actor = self.pool.pop()\n",
      "IndexError: pop from empty list\n",
      "\n",
      "During handling of the above exception, another exception occurred:\n",
      "\n",
      "Traceback (most recent call last):\n",
      "  File \"d:\\Anaconda\\envs\\TMenv\\lib\\site-packages\\flwr\\server\\superlink\\fleet\\vce\\vce_api.py\", line 112, in worker\n",
      "    out_mssg, updated_context = backend.process_message(message, context)\n",
      "  File \"d:\\Anaconda\\envs\\TMenv\\lib\\site-packages\\flwr\\server\\superlink\\fleet\\vce\\backend\\raybackend.py\", line 186, in process_message\n",
      "    self.pool.add_actor_back_to_pool(future)\n",
      "UnboundLocalError: local variable 'future' referenced before assignment\n",
      "\n",
      "\u001b[91mERROR 2025-07-12 23:24:14,017\u001b[0m:     An exception was raised when processing a message by RayBackend\n",
      "\u001b[91mERROR 2025-07-12 23:24:14,017\u001b[0m:     local variable 'future' referenced before assignment\n",
      "\u001b[91mERROR 2025-07-12 23:24:14,018\u001b[0m:     Traceback (most recent call last):\n",
      "  File \"d:\\Anaconda\\envs\\TMenv\\lib\\site-packages\\flwr\\server\\superlink\\fleet\\vce\\backend\\raybackend.py\", line 166, in process_message\n",
      "    future = self.pool.submit(\n",
      "  File \"d:\\Anaconda\\envs\\TMenv\\lib\\site-packages\\flwr\\simulation\\ray_transport\\ray_actor.py\", line 460, in submit\n",
      "    actor = self.pool.pop()\n",
      "IndexError: pop from empty list\n",
      "\n",
      "During handling of the above exception, another exception occurred:\n",
      "\n",
      "Traceback (most recent call last):\n",
      "  File \"d:\\Anaconda\\envs\\TMenv\\lib\\site-packages\\flwr\\server\\superlink\\fleet\\vce\\vce_api.py\", line 112, in worker\n",
      "    out_mssg, updated_context = backend.process_message(message, context)\n",
      "  File \"d:\\Anaconda\\envs\\TMenv\\lib\\site-packages\\flwr\\server\\superlink\\fleet\\vce\\backend\\raybackend.py\", line 186, in process_message\n",
      "    self.pool.add_actor_back_to_pool(future)\n",
      "UnboundLocalError: local variable 'future' referenced before assignment\n",
      "\n",
      "\u001b[92mINFO 2025-07-12 23:24:14,044\u001b[0m:      aggregate_fit: received 0 results and 2 failures\n",
      "\u001b[92mINFO 2025-07-12 23:24:14,045\u001b[0m:      configure_evaluate: strategy sampled 2 clients (out of 2)\n",
      "\u001b[91mERROR 2025-07-12 23:24:14,124\u001b[0m:     An exception was raised when processing a message by RayBackend\n",
      "\u001b[91mERROR 2025-07-12 23:24:14,125\u001b[0m:     local variable 'future' referenced before assignment\n",
      "\u001b[91mERROR 2025-07-12 23:24:14,125\u001b[0m:     Traceback (most recent call last):\n",
      "  File \"d:\\Anaconda\\envs\\TMenv\\lib\\site-packages\\flwr\\server\\superlink\\fleet\\vce\\backend\\raybackend.py\", line 166, in process_message\n",
      "    future = self.pool.submit(\n",
      "  File \"d:\\Anaconda\\envs\\TMenv\\lib\\site-packages\\flwr\\simulation\\ray_transport\\ray_actor.py\", line 460, in submit\n",
      "    actor = self.pool.pop()\n",
      "IndexError: pop from empty list\n",
      "\n",
      "During handling of the above exception, another exception occurred:\n",
      "\n",
      "Traceback (most recent call last):\n",
      "  File \"d:\\Anaconda\\envs\\TMenv\\lib\\site-packages\\flwr\\server\\superlink\\fleet\\vce\\vce_api.py\", line 112, in worker\n",
      "    out_mssg, updated_context = backend.process_message(message, context)\n",
      "  File \"d:\\Anaconda\\envs\\TMenv\\lib\\site-packages\\flwr\\server\\superlink\\fleet\\vce\\backend\\raybackend.py\", line 186, in process_message\n",
      "    self.pool.add_actor_back_to_pool(future)\n",
      "UnboundLocalError: local variable 'future' referenced before assignment\n",
      "\n",
      "\u001b[91mERROR 2025-07-12 23:24:14,126\u001b[0m:     An exception was raised when processing a message by RayBackend\n",
      "\u001b[91mERROR 2025-07-12 23:24:14,126\u001b[0m:     local variable 'future' referenced before assignment\n",
      "\u001b[91mERROR 2025-07-12 23:24:14,127\u001b[0m:     Traceback (most recent call last):\n",
      "  File \"d:\\Anaconda\\envs\\TMenv\\lib\\site-packages\\flwr\\server\\superlink\\fleet\\vce\\backend\\raybackend.py\", line 166, in process_message\n",
      "    future = self.pool.submit(\n",
      "  File \"d:\\Anaconda\\envs\\TMenv\\lib\\site-packages\\flwr\\simulation\\ray_transport\\ray_actor.py\", line 460, in submit\n",
      "    actor = self.pool.pop()\n",
      "IndexError: pop from empty list\n",
      "\n",
      "During handling of the above exception, another exception occurred:\n",
      "\n",
      "Traceback (most recent call last):\n",
      "  File \"d:\\Anaconda\\envs\\TMenv\\lib\\site-packages\\flwr\\server\\superlink\\fleet\\vce\\vce_api.py\", line 112, in worker\n",
      "    out_mssg, updated_context = backend.process_message(message, context)\n",
      "  File \"d:\\Anaconda\\envs\\TMenv\\lib\\site-packages\\flwr\\server\\superlink\\fleet\\vce\\backend\\raybackend.py\", line 186, in process_message\n",
      "    self.pool.add_actor_back_to_pool(future)\n",
      "UnboundLocalError: local variable 'future' referenced before assignment\n",
      "\n",
      "\u001b[92mINFO 2025-07-12 23:24:14,155\u001b[0m:      aggregate_evaluate: received 0 results and 2 failures\n",
      "\u001b[92mINFO 2025-07-12 23:24:14,155\u001b[0m:      \n",
      "\u001b[92mINFO 2025-07-12 23:24:14,156\u001b[0m:      [ROUND 21]\n",
      "\u001b[92mINFO 2025-07-12 23:24:14,157\u001b[0m:      configure_fit: strategy sampled 2 clients (out of 2)\n",
      "\u001b[91mERROR 2025-07-12 23:24:14,232\u001b[0m:     An exception was raised when processing a message by RayBackend\n",
      "\u001b[91mERROR 2025-07-12 23:24:14,233\u001b[0m:     local variable 'future' referenced before assignment\n",
      "\u001b[91mERROR 2025-07-12 23:24:14,234\u001b[0m:     Traceback (most recent call last):\n",
      "  File \"d:\\Anaconda\\envs\\TMenv\\lib\\site-packages\\flwr\\server\\superlink\\fleet\\vce\\backend\\raybackend.py\", line 166, in process_message\n",
      "    future = self.pool.submit(\n",
      "  File \"d:\\Anaconda\\envs\\TMenv\\lib\\site-packages\\flwr\\simulation\\ray_transport\\ray_actor.py\", line 460, in submit\n",
      "    actor = self.pool.pop()\n",
      "IndexError: pop from empty list\n",
      "\n",
      "During handling of the above exception, another exception occurred:\n",
      "\n",
      "Traceback (most recent call last):\n",
      "  File \"d:\\Anaconda\\envs\\TMenv\\lib\\site-packages\\flwr\\server\\superlink\\fleet\\vce\\vce_api.py\", line 112, in worker\n",
      "    out_mssg, updated_context = backend.process_message(message, context)\n",
      "  File \"d:\\Anaconda\\envs\\TMenv\\lib\\site-packages\\flwr\\server\\superlink\\fleet\\vce\\backend\\raybackend.py\", line 186, in process_message\n",
      "    self.pool.add_actor_back_to_pool(future)\n",
      "UnboundLocalError: local variable 'future' referenced before assignment\n",
      "\n",
      "\u001b[91mERROR 2025-07-12 23:24:14,234\u001b[0m:     An exception was raised when processing a message by RayBackend\n",
      "\u001b[91mERROR 2025-07-12 23:24:14,234\u001b[0m:     local variable 'future' referenced before assignment\n",
      "\u001b[91mERROR 2025-07-12 23:24:14,235\u001b[0m:     Traceback (most recent call last):\n",
      "  File \"d:\\Anaconda\\envs\\TMenv\\lib\\site-packages\\flwr\\server\\superlink\\fleet\\vce\\backend\\raybackend.py\", line 166, in process_message\n",
      "    future = self.pool.submit(\n",
      "  File \"d:\\Anaconda\\envs\\TMenv\\lib\\site-packages\\flwr\\simulation\\ray_transport\\ray_actor.py\", line 460, in submit\n",
      "    actor = self.pool.pop()\n",
      "IndexError: pop from empty list\n",
      "\n",
      "During handling of the above exception, another exception occurred:\n",
      "\n",
      "Traceback (most recent call last):\n",
      "  File \"d:\\Anaconda\\envs\\TMenv\\lib\\site-packages\\flwr\\server\\superlink\\fleet\\vce\\vce_api.py\", line 112, in worker\n",
      "    out_mssg, updated_context = backend.process_message(message, context)\n",
      "  File \"d:\\Anaconda\\envs\\TMenv\\lib\\site-packages\\flwr\\server\\superlink\\fleet\\vce\\backend\\raybackend.py\", line 186, in process_message\n",
      "    self.pool.add_actor_back_to_pool(future)\n",
      "UnboundLocalError: local variable 'future' referenced before assignment\n",
      "\n",
      "\u001b[92mINFO 2025-07-12 23:24:14,263\u001b[0m:      aggregate_fit: received 0 results and 2 failures\n",
      "\u001b[92mINFO 2025-07-12 23:24:14,264\u001b[0m:      configure_evaluate: strategy sampled 2 clients (out of 2)\n",
      "\u001b[91mERROR 2025-07-12 23:24:14,340\u001b[0m:     An exception was raised when processing a message by RayBackend\n",
      "\u001b[91mERROR 2025-07-12 23:24:14,341\u001b[0m:     local variable 'future' referenced before assignment\n",
      "\u001b[91mERROR 2025-07-12 23:24:14,342\u001b[0m:     Traceback (most recent call last):\n",
      "  File \"d:\\Anaconda\\envs\\TMenv\\lib\\site-packages\\flwr\\server\\superlink\\fleet\\vce\\backend\\raybackend.py\", line 166, in process_message\n",
      "    future = self.pool.submit(\n",
      "  File \"d:\\Anaconda\\envs\\TMenv\\lib\\site-packages\\flwr\\simulation\\ray_transport\\ray_actor.py\", line 460, in submit\n",
      "    actor = self.pool.pop()\n",
      "IndexError: pop from empty list\n",
      "\n",
      "During handling of the above exception, another exception occurred:\n",
      "\n",
      "Traceback (most recent call last):\n",
      "  File \"d:\\Anaconda\\envs\\TMenv\\lib\\site-packages\\flwr\\server\\superlink\\fleet\\vce\\vce_api.py\", line 112, in worker\n",
      "    out_mssg, updated_context = backend.process_message(message, context)\n",
      "  File \"d:\\Anaconda\\envs\\TMenv\\lib\\site-packages\\flwr\\server\\superlink\\fleet\\vce\\backend\\raybackend.py\", line 186, in process_message\n",
      "    self.pool.add_actor_back_to_pool(future)\n",
      "UnboundLocalError: local variable 'future' referenced before assignment\n",
      "\n",
      "\u001b[91mERROR 2025-07-12 23:24:14,342\u001b[0m:     An exception was raised when processing a message by RayBackend\n",
      "\u001b[91mERROR 2025-07-12 23:24:14,343\u001b[0m:     local variable 'future' referenced before assignment\n",
      "\u001b[91mERROR 2025-07-12 23:24:14,344\u001b[0m:     Traceback (most recent call last):\n",
      "  File \"d:\\Anaconda\\envs\\TMenv\\lib\\site-packages\\flwr\\server\\superlink\\fleet\\vce\\backend\\raybackend.py\", line 166, in process_message\n",
      "    future = self.pool.submit(\n",
      "  File \"d:\\Anaconda\\envs\\TMenv\\lib\\site-packages\\flwr\\simulation\\ray_transport\\ray_actor.py\", line 460, in submit\n",
      "    actor = self.pool.pop()\n",
      "IndexError: pop from empty list\n",
      "\n",
      "During handling of the above exception, another exception occurred:\n",
      "\n",
      "Traceback (most recent call last):\n",
      "  File \"d:\\Anaconda\\envs\\TMenv\\lib\\site-packages\\flwr\\server\\superlink\\fleet\\vce\\vce_api.py\", line 112, in worker\n",
      "    out_mssg, updated_context = backend.process_message(message, context)\n",
      "  File \"d:\\Anaconda\\envs\\TMenv\\lib\\site-packages\\flwr\\server\\superlink\\fleet\\vce\\backend\\raybackend.py\", line 186, in process_message\n",
      "    self.pool.add_actor_back_to_pool(future)\n",
      "UnboundLocalError: local variable 'future' referenced before assignment\n",
      "\n",
      "\u001b[92mINFO 2025-07-12 23:24:14,372\u001b[0m:      aggregate_evaluate: received 0 results and 2 failures\n",
      "\u001b[92mINFO 2025-07-12 23:24:14,373\u001b[0m:      \n",
      "\u001b[92mINFO 2025-07-12 23:24:14,373\u001b[0m:      [ROUND 22]\n",
      "\u001b[92mINFO 2025-07-12 23:24:14,374\u001b[0m:      configure_fit: strategy sampled 2 clients (out of 2)\n",
      "\u001b[91mERROR 2025-07-12 23:24:14,449\u001b[0m:     An exception was raised when processing a message by RayBackend\n",
      "\u001b[91mERROR 2025-07-12 23:24:14,449\u001b[0m:     local variable 'future' referenced before assignment\n",
      "\u001b[91mERROR 2025-07-12 23:24:14,450\u001b[0m:     Traceback (most recent call last):\n",
      "  File \"d:\\Anaconda\\envs\\TMenv\\lib\\site-packages\\flwr\\server\\superlink\\fleet\\vce\\backend\\raybackend.py\", line 166, in process_message\n",
      "    future = self.pool.submit(\n",
      "  File \"d:\\Anaconda\\envs\\TMenv\\lib\\site-packages\\flwr\\simulation\\ray_transport\\ray_actor.py\", line 460, in submit\n",
      "    actor = self.pool.pop()\n",
      "IndexError: pop from empty list\n",
      "\n",
      "During handling of the above exception, another exception occurred:\n",
      "\n",
      "Traceback (most recent call last):\n",
      "  File \"d:\\Anaconda\\envs\\TMenv\\lib\\site-packages\\flwr\\server\\superlink\\fleet\\vce\\vce_api.py\", line 112, in worker\n",
      "    out_mssg, updated_context = backend.process_message(message, context)\n",
      "  File \"d:\\Anaconda\\envs\\TMenv\\lib\\site-packages\\flwr\\server\\superlink\\fleet\\vce\\backend\\raybackend.py\", line 186, in process_message\n",
      "    self.pool.add_actor_back_to_pool(future)\n",
      "UnboundLocalError: local variable 'future' referenced before assignment\n",
      "\n",
      "\u001b[91mERROR 2025-07-12 23:24:14,451\u001b[0m:     An exception was raised when processing a message by RayBackend\n",
      "\u001b[91mERROR 2025-07-12 23:24:14,451\u001b[0m:     local variable 'future' referenced before assignment\n",
      "\u001b[91mERROR 2025-07-12 23:24:14,452\u001b[0m:     Traceback (most recent call last):\n",
      "  File \"d:\\Anaconda\\envs\\TMenv\\lib\\site-packages\\flwr\\server\\superlink\\fleet\\vce\\backend\\raybackend.py\", line 166, in process_message\n",
      "    future = self.pool.submit(\n",
      "  File \"d:\\Anaconda\\envs\\TMenv\\lib\\site-packages\\flwr\\simulation\\ray_transport\\ray_actor.py\", line 460, in submit\n",
      "    actor = self.pool.pop()\n",
      "IndexError: pop from empty list\n",
      "\n",
      "During handling of the above exception, another exception occurred:\n",
      "\n",
      "Traceback (most recent call last):\n",
      "  File \"d:\\Anaconda\\envs\\TMenv\\lib\\site-packages\\flwr\\server\\superlink\\fleet\\vce\\vce_api.py\", line 112, in worker\n",
      "    out_mssg, updated_context = backend.process_message(message, context)\n",
      "  File \"d:\\Anaconda\\envs\\TMenv\\lib\\site-packages\\flwr\\server\\superlink\\fleet\\vce\\backend\\raybackend.py\", line 186, in process_message\n",
      "    self.pool.add_actor_back_to_pool(future)\n",
      "UnboundLocalError: local variable 'future' referenced before assignment\n",
      "\n",
      "\u001b[92mINFO 2025-07-12 23:24:14,479\u001b[0m:      aggregate_fit: received 0 results and 2 failures\n",
      "\u001b[92mINFO 2025-07-12 23:24:14,480\u001b[0m:      configure_evaluate: strategy sampled 2 clients (out of 2)\n",
      "\u001b[91mERROR 2025-07-12 23:24:14,557\u001b[0m:     An exception was raised when processing a message by RayBackend\n",
      "\u001b[91mERROR 2025-07-12 23:24:14,557\u001b[0m:     local variable 'future' referenced before assignment\n",
      "\u001b[91mERROR 2025-07-12 23:24:14,558\u001b[0m:     Traceback (most recent call last):\n",
      "  File \"d:\\Anaconda\\envs\\TMenv\\lib\\site-packages\\flwr\\server\\superlink\\fleet\\vce\\backend\\raybackend.py\", line 166, in process_message\n",
      "    future = self.pool.submit(\n",
      "  File \"d:\\Anaconda\\envs\\TMenv\\lib\\site-packages\\flwr\\simulation\\ray_transport\\ray_actor.py\", line 460, in submit\n",
      "    actor = self.pool.pop()\n",
      "IndexError: pop from empty list\n",
      "\n",
      "During handling of the above exception, another exception occurred:\n",
      "\n",
      "Traceback (most recent call last):\n",
      "  File \"d:\\Anaconda\\envs\\TMenv\\lib\\site-packages\\flwr\\server\\superlink\\fleet\\vce\\vce_api.py\", line 112, in worker\n",
      "    out_mssg, updated_context = backend.process_message(message, context)\n",
      "  File \"d:\\Anaconda\\envs\\TMenv\\lib\\site-packages\\flwr\\server\\superlink\\fleet\\vce\\backend\\raybackend.py\", line 186, in process_message\n",
      "    self.pool.add_actor_back_to_pool(future)\n",
      "UnboundLocalError: local variable 'future' referenced before assignment\n",
      "\n",
      "\u001b[91mERROR 2025-07-12 23:24:14,559\u001b[0m:     An exception was raised when processing a message by RayBackend\n",
      "\u001b[91mERROR 2025-07-12 23:24:14,559\u001b[0m:     local variable 'future' referenced before assignment\n",
      "\u001b[91mERROR 2025-07-12 23:24:14,560\u001b[0m:     Traceback (most recent call last):\n",
      "  File \"d:\\Anaconda\\envs\\TMenv\\lib\\site-packages\\flwr\\server\\superlink\\fleet\\vce\\backend\\raybackend.py\", line 166, in process_message\n",
      "    future = self.pool.submit(\n",
      "  File \"d:\\Anaconda\\envs\\TMenv\\lib\\site-packages\\flwr\\simulation\\ray_transport\\ray_actor.py\", line 460, in submit\n",
      "    actor = self.pool.pop()\n",
      "IndexError: pop from empty list\n",
      "\n",
      "During handling of the above exception, another exception occurred:\n",
      "\n",
      "Traceback (most recent call last):\n",
      "  File \"d:\\Anaconda\\envs\\TMenv\\lib\\site-packages\\flwr\\server\\superlink\\fleet\\vce\\vce_api.py\", line 112, in worker\n",
      "    out_mssg, updated_context = backend.process_message(message, context)\n",
      "  File \"d:\\Anaconda\\envs\\TMenv\\lib\\site-packages\\flwr\\server\\superlink\\fleet\\vce\\backend\\raybackend.py\", line 186, in process_message\n",
      "    self.pool.add_actor_back_to_pool(future)\n",
      "UnboundLocalError: local variable 'future' referenced before assignment\n",
      "\n",
      "\u001b[92mINFO 2025-07-12 23:24:14,587\u001b[0m:      aggregate_evaluate: received 0 results and 2 failures\n",
      "\u001b[92mINFO 2025-07-12 23:24:14,588\u001b[0m:      \n",
      "\u001b[92mINFO 2025-07-12 23:24:14,588\u001b[0m:      [ROUND 23]\n",
      "\u001b[92mINFO 2025-07-12 23:24:14,588\u001b[0m:      configure_fit: strategy sampled 2 clients (out of 2)\n",
      "\u001b[91mERROR 2025-07-12 23:24:14,666\u001b[0m:     An exception was raised when processing a message by RayBackend\n",
      "\u001b[91mERROR 2025-07-12 23:24:14,667\u001b[0m:     local variable 'future' referenced before assignment\n",
      "\u001b[91mERROR 2025-07-12 23:24:14,668\u001b[0m:     Traceback (most recent call last):\n",
      "  File \"d:\\Anaconda\\envs\\TMenv\\lib\\site-packages\\flwr\\server\\superlink\\fleet\\vce\\backend\\raybackend.py\", line 166, in process_message\n",
      "    future = self.pool.submit(\n",
      "  File \"d:\\Anaconda\\envs\\TMenv\\lib\\site-packages\\flwr\\simulation\\ray_transport\\ray_actor.py\", line 460, in submit\n",
      "    actor = self.pool.pop()\n",
      "IndexError: pop from empty list\n",
      "\n",
      "During handling of the above exception, another exception occurred:\n",
      "\n",
      "Traceback (most recent call last):\n",
      "  File \"d:\\Anaconda\\envs\\TMenv\\lib\\site-packages\\flwr\\server\\superlink\\fleet\\vce\\vce_api.py\", line 112, in worker\n",
      "    out_mssg, updated_context = backend.process_message(message, context)\n",
      "  File \"d:\\Anaconda\\envs\\TMenv\\lib\\site-packages\\flwr\\server\\superlink\\fleet\\vce\\backend\\raybackend.py\", line 186, in process_message\n",
      "    self.pool.add_actor_back_to_pool(future)\n",
      "UnboundLocalError: local variable 'future' referenced before assignment\n",
      "\n",
      "\u001b[91mERROR 2025-07-12 23:24:14,668\u001b[0m:     An exception was raised when processing a message by RayBackend\n",
      "\u001b[91mERROR 2025-07-12 23:24:14,669\u001b[0m:     local variable 'future' referenced before assignment\n",
      "\u001b[91mERROR 2025-07-12 23:24:14,670\u001b[0m:     Traceback (most recent call last):\n",
      "  File \"d:\\Anaconda\\envs\\TMenv\\lib\\site-packages\\flwr\\server\\superlink\\fleet\\vce\\backend\\raybackend.py\", line 166, in process_message\n",
      "    future = self.pool.submit(\n",
      "  File \"d:\\Anaconda\\envs\\TMenv\\lib\\site-packages\\flwr\\simulation\\ray_transport\\ray_actor.py\", line 460, in submit\n",
      "    actor = self.pool.pop()\n",
      "IndexError: pop from empty list\n",
      "\n",
      "During handling of the above exception, another exception occurred:\n",
      "\n",
      "Traceback (most recent call last):\n",
      "  File \"d:\\Anaconda\\envs\\TMenv\\lib\\site-packages\\flwr\\server\\superlink\\fleet\\vce\\vce_api.py\", line 112, in worker\n",
      "    out_mssg, updated_context = backend.process_message(message, context)\n",
      "  File \"d:\\Anaconda\\envs\\TMenv\\lib\\site-packages\\flwr\\server\\superlink\\fleet\\vce\\backend\\raybackend.py\", line 186, in process_message\n",
      "    self.pool.add_actor_back_to_pool(future)\n",
      "UnboundLocalError: local variable 'future' referenced before assignment\n",
      "\n",
      "\u001b[92mINFO 2025-07-12 23:24:14,697\u001b[0m:      aggregate_fit: received 0 results and 2 failures\n",
      "\u001b[92mINFO 2025-07-12 23:24:14,698\u001b[0m:      configure_evaluate: strategy sampled 2 clients (out of 2)\n",
      "\u001b[91mERROR 2025-07-12 23:24:14,774\u001b[0m:     An exception was raised when processing a message by RayBackend\n",
      "\u001b[91mERROR 2025-07-12 23:24:14,775\u001b[0m:     local variable 'future' referenced before assignment\n",
      "\u001b[91mERROR 2025-07-12 23:24:14,776\u001b[0m:     Traceback (most recent call last):\n",
      "  File \"d:\\Anaconda\\envs\\TMenv\\lib\\site-packages\\flwr\\server\\superlink\\fleet\\vce\\backend\\raybackend.py\", line 166, in process_message\n",
      "    future = self.pool.submit(\n",
      "  File \"d:\\Anaconda\\envs\\TMenv\\lib\\site-packages\\flwr\\simulation\\ray_transport\\ray_actor.py\", line 460, in submit\n",
      "    actor = self.pool.pop()\n",
      "IndexError: pop from empty list\n",
      "\n",
      "During handling of the above exception, another exception occurred:\n",
      "\n",
      "Traceback (most recent call last):\n",
      "  File \"d:\\Anaconda\\envs\\TMenv\\lib\\site-packages\\flwr\\server\\superlink\\fleet\\vce\\vce_api.py\", line 112, in worker\n",
      "    out_mssg, updated_context = backend.process_message(message, context)\n",
      "  File \"d:\\Anaconda\\envs\\TMenv\\lib\\site-packages\\flwr\\server\\superlink\\fleet\\vce\\backend\\raybackend.py\", line 186, in process_message\n",
      "    self.pool.add_actor_back_to_pool(future)\n",
      "UnboundLocalError: local variable 'future' referenced before assignment\n",
      "\n",
      "\u001b[91mERROR 2025-07-12 23:24:14,777\u001b[0m:     An exception was raised when processing a message by RayBackend\n",
      "\u001b[91mERROR 2025-07-12 23:24:14,777\u001b[0m:     local variable 'future' referenced before assignment\n",
      "\u001b[91mERROR 2025-07-12 23:24:14,778\u001b[0m:     Traceback (most recent call last):\n",
      "  File \"d:\\Anaconda\\envs\\TMenv\\lib\\site-packages\\flwr\\server\\superlink\\fleet\\vce\\backend\\raybackend.py\", line 166, in process_message\n",
      "    future = self.pool.submit(\n",
      "  File \"d:\\Anaconda\\envs\\TMenv\\lib\\site-packages\\flwr\\simulation\\ray_transport\\ray_actor.py\", line 460, in submit\n",
      "    actor = self.pool.pop()\n",
      "IndexError: pop from empty list\n",
      "\n",
      "During handling of the above exception, another exception occurred:\n",
      "\n",
      "Traceback (most recent call last):\n",
      "  File \"d:\\Anaconda\\envs\\TMenv\\lib\\site-packages\\flwr\\server\\superlink\\fleet\\vce\\vce_api.py\", line 112, in worker\n",
      "    out_mssg, updated_context = backend.process_message(message, context)\n",
      "  File \"d:\\Anaconda\\envs\\TMenv\\lib\\site-packages\\flwr\\server\\superlink\\fleet\\vce\\backend\\raybackend.py\", line 186, in process_message\n",
      "    self.pool.add_actor_back_to_pool(future)\n",
      "UnboundLocalError: local variable 'future' referenced before assignment\n",
      "\n",
      "\u001b[92mINFO 2025-07-12 23:24:14,805\u001b[0m:      aggregate_evaluate: received 0 results and 2 failures\n",
      "\u001b[92mINFO 2025-07-12 23:24:14,806\u001b[0m:      \n",
      "\u001b[92mINFO 2025-07-12 23:24:14,806\u001b[0m:      [ROUND 24]\n",
      "\u001b[92mINFO 2025-07-12 23:24:14,807\u001b[0m:      configure_fit: strategy sampled 2 clients (out of 2)\n",
      "\u001b[91mERROR 2025-07-12 23:24:14,883\u001b[0m:     An exception was raised when processing a message by RayBackend\n",
      "\u001b[91mERROR 2025-07-12 23:24:14,884\u001b[0m:     local variable 'future' referenced before assignment\n",
      "\u001b[91mERROR 2025-07-12 23:24:14,885\u001b[0m:     Traceback (most recent call last):\n",
      "  File \"d:\\Anaconda\\envs\\TMenv\\lib\\site-packages\\flwr\\server\\superlink\\fleet\\vce\\backend\\raybackend.py\", line 166, in process_message\n",
      "    future = self.pool.submit(\n",
      "  File \"d:\\Anaconda\\envs\\TMenv\\lib\\site-packages\\flwr\\simulation\\ray_transport\\ray_actor.py\", line 460, in submit\n",
      "    actor = self.pool.pop()\n",
      "IndexError: pop from empty list\n",
      "\n",
      "During handling of the above exception, another exception occurred:\n",
      "\n",
      "Traceback (most recent call last):\n",
      "  File \"d:\\Anaconda\\envs\\TMenv\\lib\\site-packages\\flwr\\server\\superlink\\fleet\\vce\\vce_api.py\", line 112, in worker\n",
      "    out_mssg, updated_context = backend.process_message(message, context)\n",
      "  File \"d:\\Anaconda\\envs\\TMenv\\lib\\site-packages\\flwr\\server\\superlink\\fleet\\vce\\backend\\raybackend.py\", line 186, in process_message\n",
      "    self.pool.add_actor_back_to_pool(future)\n",
      "UnboundLocalError: local variable 'future' referenced before assignment\n",
      "\n",
      "\u001b[91mERROR 2025-07-12 23:24:14,886\u001b[0m:     An exception was raised when processing a message by RayBackend\n",
      "\u001b[91mERROR 2025-07-12 23:24:14,887\u001b[0m:     local variable 'future' referenced before assignment\n",
      "\u001b[91mERROR 2025-07-12 23:24:14,887\u001b[0m:     Traceback (most recent call last):\n",
      "  File \"d:\\Anaconda\\envs\\TMenv\\lib\\site-packages\\flwr\\server\\superlink\\fleet\\vce\\backend\\raybackend.py\", line 166, in process_message\n",
      "    future = self.pool.submit(\n",
      "  File \"d:\\Anaconda\\envs\\TMenv\\lib\\site-packages\\flwr\\simulation\\ray_transport\\ray_actor.py\", line 460, in submit\n",
      "    actor = self.pool.pop()\n",
      "IndexError: pop from empty list\n",
      "\n",
      "During handling of the above exception, another exception occurred:\n",
      "\n",
      "Traceback (most recent call last):\n",
      "  File \"d:\\Anaconda\\envs\\TMenv\\lib\\site-packages\\flwr\\server\\superlink\\fleet\\vce\\vce_api.py\", line 112, in worker\n",
      "    out_mssg, updated_context = backend.process_message(message, context)\n",
      "  File \"d:\\Anaconda\\envs\\TMenv\\lib\\site-packages\\flwr\\server\\superlink\\fleet\\vce\\backend\\raybackend.py\", line 186, in process_message\n",
      "    self.pool.add_actor_back_to_pool(future)\n",
      "UnboundLocalError: local variable 'future' referenced before assignment\n",
      "\n",
      "\u001b[92mINFO 2025-07-12 23:24:14,914\u001b[0m:      aggregate_fit: received 0 results and 2 failures\n",
      "\u001b[92mINFO 2025-07-12 23:24:14,915\u001b[0m:      configure_evaluate: strategy sampled 2 clients (out of 2)\n",
      "\u001b[91mERROR 2025-07-12 23:24:14,992\u001b[0m:     An exception was raised when processing a message by RayBackend\n",
      "\u001b[91mERROR 2025-07-12 23:24:14,993\u001b[0m:     local variable 'future' referenced before assignment\n",
      "\u001b[91mERROR 2025-07-12 23:24:14,994\u001b[0m:     Traceback (most recent call last):\n",
      "  File \"d:\\Anaconda\\envs\\TMenv\\lib\\site-packages\\flwr\\server\\superlink\\fleet\\vce\\backend\\raybackend.py\", line 166, in process_message\n",
      "    future = self.pool.submit(\n",
      "  File \"d:\\Anaconda\\envs\\TMenv\\lib\\site-packages\\flwr\\simulation\\ray_transport\\ray_actor.py\", line 460, in submit\n",
      "    actor = self.pool.pop()\n",
      "IndexError: pop from empty list\n",
      "\n",
      "During handling of the above exception, another exception occurred:\n",
      "\n",
      "Traceback (most recent call last):\n",
      "  File \"d:\\Anaconda\\envs\\TMenv\\lib\\site-packages\\flwr\\server\\superlink\\fleet\\vce\\vce_api.py\", line 112, in worker\n",
      "    out_mssg, updated_context = backend.process_message(message, context)\n",
      "  File \"d:\\Anaconda\\envs\\TMenv\\lib\\site-packages\\flwr\\server\\superlink\\fleet\\vce\\backend\\raybackend.py\", line 186, in process_message\n",
      "    self.pool.add_actor_back_to_pool(future)\n",
      "UnboundLocalError: local variable 'future' referenced before assignment\n",
      "\n",
      "\u001b[91mERROR 2025-07-12 23:24:14,994\u001b[0m:     An exception was raised when processing a message by RayBackend\n",
      "\u001b[91mERROR 2025-07-12 23:24:14,995\u001b[0m:     local variable 'future' referenced before assignment\n",
      "\u001b[91mERROR 2025-07-12 23:24:14,996\u001b[0m:     Traceback (most recent call last):\n",
      "  File \"d:\\Anaconda\\envs\\TMenv\\lib\\site-packages\\flwr\\server\\superlink\\fleet\\vce\\backend\\raybackend.py\", line 166, in process_message\n",
      "    future = self.pool.submit(\n",
      "  File \"d:\\Anaconda\\envs\\TMenv\\lib\\site-packages\\flwr\\simulation\\ray_transport\\ray_actor.py\", line 460, in submit\n",
      "    actor = self.pool.pop()\n",
      "IndexError: pop from empty list\n",
      "\n",
      "During handling of the above exception, another exception occurred:\n",
      "\n",
      "Traceback (most recent call last):\n",
      "  File \"d:\\Anaconda\\envs\\TMenv\\lib\\site-packages\\flwr\\server\\superlink\\fleet\\vce\\vce_api.py\", line 112, in worker\n",
      "    out_mssg, updated_context = backend.process_message(message, context)\n",
      "  File \"d:\\Anaconda\\envs\\TMenv\\lib\\site-packages\\flwr\\server\\superlink\\fleet\\vce\\backend\\raybackend.py\", line 186, in process_message\n",
      "    self.pool.add_actor_back_to_pool(future)\n",
      "UnboundLocalError: local variable 'future' referenced before assignment\n",
      "\n",
      "\u001b[92mINFO 2025-07-12 23:24:15,023\u001b[0m:      aggregate_evaluate: received 0 results and 2 failures\n",
      "\u001b[92mINFO 2025-07-12 23:24:15,024\u001b[0m:      \n",
      "\u001b[92mINFO 2025-07-12 23:24:15,025\u001b[0m:      [ROUND 25]\n",
      "\u001b[92mINFO 2025-07-12 23:24:15,025\u001b[0m:      configure_fit: strategy sampled 2 clients (out of 2)\n",
      "\u001b[91mERROR 2025-07-12 23:24:15,099\u001b[0m:     An exception was raised when processing a message by RayBackend\n",
      "\u001b[91mERROR 2025-07-12 23:24:15,100\u001b[0m:     local variable 'future' referenced before assignment\n",
      "\u001b[91mERROR 2025-07-12 23:24:15,101\u001b[0m:     Traceback (most recent call last):\n",
      "  File \"d:\\Anaconda\\envs\\TMenv\\lib\\site-packages\\flwr\\server\\superlink\\fleet\\vce\\backend\\raybackend.py\", line 166, in process_message\n",
      "    future = self.pool.submit(\n",
      "  File \"d:\\Anaconda\\envs\\TMenv\\lib\\site-packages\\flwr\\simulation\\ray_transport\\ray_actor.py\", line 460, in submit\n",
      "    actor = self.pool.pop()\n",
      "IndexError: pop from empty list\n",
      "\n",
      "During handling of the above exception, another exception occurred:\n",
      "\n",
      "Traceback (most recent call last):\n",
      "  File \"d:\\Anaconda\\envs\\TMenv\\lib\\site-packages\\flwr\\server\\superlink\\fleet\\vce\\vce_api.py\", line 112, in worker\n",
      "    out_mssg, updated_context = backend.process_message(message, context)\n",
      "  File \"d:\\Anaconda\\envs\\TMenv\\lib\\site-packages\\flwr\\server\\superlink\\fleet\\vce\\backend\\raybackend.py\", line 186, in process_message\n",
      "    self.pool.add_actor_back_to_pool(future)\n",
      "UnboundLocalError: local variable 'future' referenced before assignment\n",
      "\n",
      "\u001b[91mERROR 2025-07-12 23:24:15,101\u001b[0m:     An exception was raised when processing a message by RayBackend\n",
      "\u001b[91mERROR 2025-07-12 23:24:15,102\u001b[0m:     local variable 'future' referenced before assignment\n",
      "\u001b[91mERROR 2025-07-12 23:24:15,103\u001b[0m:     Traceback (most recent call last):\n",
      "  File \"d:\\Anaconda\\envs\\TMenv\\lib\\site-packages\\flwr\\server\\superlink\\fleet\\vce\\backend\\raybackend.py\", line 166, in process_message\n",
      "    future = self.pool.submit(\n",
      "  File \"d:\\Anaconda\\envs\\TMenv\\lib\\site-packages\\flwr\\simulation\\ray_transport\\ray_actor.py\", line 460, in submit\n",
      "    actor = self.pool.pop()\n",
      "IndexError: pop from empty list\n",
      "\n",
      "During handling of the above exception, another exception occurred:\n",
      "\n",
      "Traceback (most recent call last):\n",
      "  File \"d:\\Anaconda\\envs\\TMenv\\lib\\site-packages\\flwr\\server\\superlink\\fleet\\vce\\vce_api.py\", line 112, in worker\n",
      "    out_mssg, updated_context = backend.process_message(message, context)\n",
      "  File \"d:\\Anaconda\\envs\\TMenv\\lib\\site-packages\\flwr\\server\\superlink\\fleet\\vce\\backend\\raybackend.py\", line 186, in process_message\n",
      "    self.pool.add_actor_back_to_pool(future)\n",
      "UnboundLocalError: local variable 'future' referenced before assignment\n",
      "\n",
      "\u001b[92mINFO 2025-07-12 23:24:15,129\u001b[0m:      aggregate_fit: received 0 results and 2 failures\n",
      "\u001b[92mINFO 2025-07-12 23:24:15,130\u001b[0m:      configure_evaluate: strategy sampled 2 clients (out of 2)\n",
      "\u001b[91mERROR 2025-07-12 23:24:15,206\u001b[0m:     An exception was raised when processing a message by RayBackend\n",
      "\u001b[91mERROR 2025-07-12 23:24:15,207\u001b[0m:     local variable 'future' referenced before assignment\n",
      "\u001b[91mERROR 2025-07-12 23:24:15,208\u001b[0m:     Traceback (most recent call last):\n",
      "  File \"d:\\Anaconda\\envs\\TMenv\\lib\\site-packages\\flwr\\server\\superlink\\fleet\\vce\\backend\\raybackend.py\", line 166, in process_message\n",
      "    future = self.pool.submit(\n",
      "  File \"d:\\Anaconda\\envs\\TMenv\\lib\\site-packages\\flwr\\simulation\\ray_transport\\ray_actor.py\", line 460, in submit\n",
      "    actor = self.pool.pop()\n",
      "IndexError: pop from empty list\n",
      "\n",
      "During handling of the above exception, another exception occurred:\n",
      "\n",
      "Traceback (most recent call last):\n",
      "  File \"d:\\Anaconda\\envs\\TMenv\\lib\\site-packages\\flwr\\server\\superlink\\fleet\\vce\\vce_api.py\", line 112, in worker\n",
      "    out_mssg, updated_context = backend.process_message(message, context)\n",
      "  File \"d:\\Anaconda\\envs\\TMenv\\lib\\site-packages\\flwr\\server\\superlink\\fleet\\vce\\backend\\raybackend.py\", line 186, in process_message\n",
      "    self.pool.add_actor_back_to_pool(future)\n",
      "UnboundLocalError: local variable 'future' referenced before assignment\n",
      "\n",
      "\u001b[91mERROR 2025-07-12 23:24:15,208\u001b[0m:     An exception was raised when processing a message by RayBackend\n",
      "\u001b[91mERROR 2025-07-12 23:24:15,209\u001b[0m:     local variable 'future' referenced before assignment\n",
      "\u001b[91mERROR 2025-07-12 23:24:15,210\u001b[0m:     Traceback (most recent call last):\n",
      "  File \"d:\\Anaconda\\envs\\TMenv\\lib\\site-packages\\flwr\\server\\superlink\\fleet\\vce\\backend\\raybackend.py\", line 166, in process_message\n",
      "    future = self.pool.submit(\n",
      "  File \"d:\\Anaconda\\envs\\TMenv\\lib\\site-packages\\flwr\\simulation\\ray_transport\\ray_actor.py\", line 460, in submit\n",
      "    actor = self.pool.pop()\n",
      "IndexError: pop from empty list\n",
      "\n",
      "During handling of the above exception, another exception occurred:\n",
      "\n",
      "Traceback (most recent call last):\n",
      "  File \"d:\\Anaconda\\envs\\TMenv\\lib\\site-packages\\flwr\\server\\superlink\\fleet\\vce\\vce_api.py\", line 112, in worker\n",
      "    out_mssg, updated_context = backend.process_message(message, context)\n",
      "  File \"d:\\Anaconda\\envs\\TMenv\\lib\\site-packages\\flwr\\server\\superlink\\fleet\\vce\\backend\\raybackend.py\", line 186, in process_message\n",
      "    self.pool.add_actor_back_to_pool(future)\n",
      "UnboundLocalError: local variable 'future' referenced before assignment\n",
      "\n",
      "\u001b[92mINFO 2025-07-12 23:24:15,236\u001b[0m:      aggregate_evaluate: received 0 results and 2 failures\n",
      "\u001b[92mINFO 2025-07-12 23:24:15,237\u001b[0m:      \n",
      "\u001b[92mINFO 2025-07-12 23:24:15,237\u001b[0m:      [ROUND 26]\n",
      "\u001b[92mINFO 2025-07-12 23:24:15,237\u001b[0m:      configure_fit: strategy sampled 2 clients (out of 2)\n",
      "\u001b[91mERROR 2025-07-12 23:24:15,313\u001b[0m:     An exception was raised when processing a message by RayBackend\n",
      "\u001b[91mERROR 2025-07-12 23:24:15,314\u001b[0m:     local variable 'future' referenced before assignment\n",
      "\u001b[91mERROR 2025-07-12 23:24:15,315\u001b[0m:     Traceback (most recent call last):\n",
      "  File \"d:\\Anaconda\\envs\\TMenv\\lib\\site-packages\\flwr\\server\\superlink\\fleet\\vce\\backend\\raybackend.py\", line 166, in process_message\n",
      "    future = self.pool.submit(\n",
      "  File \"d:\\Anaconda\\envs\\TMenv\\lib\\site-packages\\flwr\\simulation\\ray_transport\\ray_actor.py\", line 460, in submit\n",
      "    actor = self.pool.pop()\n",
      "IndexError: pop from empty list\n",
      "\n",
      "During handling of the above exception, another exception occurred:\n",
      "\n",
      "Traceback (most recent call last):\n",
      "  File \"d:\\Anaconda\\envs\\TMenv\\lib\\site-packages\\flwr\\server\\superlink\\fleet\\vce\\vce_api.py\", line 112, in worker\n",
      "    out_mssg, updated_context = backend.process_message(message, context)\n",
      "  File \"d:\\Anaconda\\envs\\TMenv\\lib\\site-packages\\flwr\\server\\superlink\\fleet\\vce\\backend\\raybackend.py\", line 186, in process_message\n",
      "    self.pool.add_actor_back_to_pool(future)\n",
      "UnboundLocalError: local variable 'future' referenced before assignment\n",
      "\n",
      "\u001b[91mERROR 2025-07-12 23:24:15,316\u001b[0m:     An exception was raised when processing a message by RayBackend\n",
      "\u001b[91mERROR 2025-07-12 23:24:15,317\u001b[0m:     local variable 'future' referenced before assignment\n",
      "\u001b[91mERROR 2025-07-12 23:24:15,318\u001b[0m:     Traceback (most recent call last):\n",
      "  File \"d:\\Anaconda\\envs\\TMenv\\lib\\site-packages\\flwr\\server\\superlink\\fleet\\vce\\backend\\raybackend.py\", line 166, in process_message\n",
      "    future = self.pool.submit(\n",
      "  File \"d:\\Anaconda\\envs\\TMenv\\lib\\site-packages\\flwr\\simulation\\ray_transport\\ray_actor.py\", line 460, in submit\n",
      "    actor = self.pool.pop()\n",
      "IndexError: pop from empty list\n",
      "\n",
      "During handling of the above exception, another exception occurred:\n",
      "\n",
      "Traceback (most recent call last):\n",
      "  File \"d:\\Anaconda\\envs\\TMenv\\lib\\site-packages\\flwr\\server\\superlink\\fleet\\vce\\vce_api.py\", line 112, in worker\n",
      "    out_mssg, updated_context = backend.process_message(message, context)\n",
      "  File \"d:\\Anaconda\\envs\\TMenv\\lib\\site-packages\\flwr\\server\\superlink\\fleet\\vce\\backend\\raybackend.py\", line 186, in process_message\n",
      "    self.pool.add_actor_back_to_pool(future)\n",
      "UnboundLocalError: local variable 'future' referenced before assignment\n",
      "\n",
      "\u001b[92mINFO 2025-07-12 23:24:15,344\u001b[0m:      aggregate_fit: received 0 results and 2 failures\n",
      "\u001b[92mINFO 2025-07-12 23:24:15,345\u001b[0m:      configure_evaluate: strategy sampled 2 clients (out of 2)\n",
      "\u001b[91mERROR 2025-07-12 23:24:15,421\u001b[0m:     An exception was raised when processing a message by RayBackend\n",
      "\u001b[91mERROR 2025-07-12 23:24:15,423\u001b[0m:     local variable 'future' referenced before assignment\n",
      "\u001b[91mERROR 2025-07-12 23:24:15,424\u001b[0m:     Traceback (most recent call last):\n",
      "  File \"d:\\Anaconda\\envs\\TMenv\\lib\\site-packages\\flwr\\server\\superlink\\fleet\\vce\\backend\\raybackend.py\", line 166, in process_message\n",
      "    future = self.pool.submit(\n",
      "  File \"d:\\Anaconda\\envs\\TMenv\\lib\\site-packages\\flwr\\simulation\\ray_transport\\ray_actor.py\", line 460, in submit\n",
      "    actor = self.pool.pop()\n",
      "IndexError: pop from empty list\n",
      "\n",
      "During handling of the above exception, another exception occurred:\n",
      "\n",
      "Traceback (most recent call last):\n",
      "  File \"d:\\Anaconda\\envs\\TMenv\\lib\\site-packages\\flwr\\server\\superlink\\fleet\\vce\\vce_api.py\", line 112, in worker\n",
      "    out_mssg, updated_context = backend.process_message(message, context)\n",
      "  File \"d:\\Anaconda\\envs\\TMenv\\lib\\site-packages\\flwr\\server\\superlink\\fleet\\vce\\backend\\raybackend.py\", line 186, in process_message\n",
      "    self.pool.add_actor_back_to_pool(future)\n",
      "UnboundLocalError: local variable 'future' referenced before assignment\n",
      "\n",
      "\u001b[91mERROR 2025-07-12 23:24:15,424\u001b[0m:     An exception was raised when processing a message by RayBackend\n",
      "\u001b[91mERROR 2025-07-12 23:24:15,425\u001b[0m:     local variable 'future' referenced before assignment\n",
      "\u001b[91mERROR 2025-07-12 23:24:15,426\u001b[0m:     Traceback (most recent call last):\n",
      "  File \"d:\\Anaconda\\envs\\TMenv\\lib\\site-packages\\flwr\\server\\superlink\\fleet\\vce\\backend\\raybackend.py\", line 166, in process_message\n",
      "    future = self.pool.submit(\n",
      "  File \"d:\\Anaconda\\envs\\TMenv\\lib\\site-packages\\flwr\\simulation\\ray_transport\\ray_actor.py\", line 460, in submit\n",
      "    actor = self.pool.pop()\n",
      "IndexError: pop from empty list\n",
      "\n",
      "During handling of the above exception, another exception occurred:\n",
      "\n",
      "Traceback (most recent call last):\n",
      "  File \"d:\\Anaconda\\envs\\TMenv\\lib\\site-packages\\flwr\\server\\superlink\\fleet\\vce\\vce_api.py\", line 112, in worker\n",
      "    out_mssg, updated_context = backend.process_message(message, context)\n",
      "  File \"d:\\Anaconda\\envs\\TMenv\\lib\\site-packages\\flwr\\server\\superlink\\fleet\\vce\\backend\\raybackend.py\", line 186, in process_message\n",
      "    self.pool.add_actor_back_to_pool(future)\n",
      "UnboundLocalError: local variable 'future' referenced before assignment\n",
      "\n",
      "\u001b[92mINFO 2025-07-12 23:24:15,453\u001b[0m:      aggregate_evaluate: received 0 results and 2 failures\n",
      "\u001b[92mINFO 2025-07-12 23:24:15,454\u001b[0m:      \n",
      "\u001b[92mINFO 2025-07-12 23:24:15,455\u001b[0m:      [ROUND 27]\n",
      "\u001b[92mINFO 2025-07-12 23:24:15,455\u001b[0m:      configure_fit: strategy sampled 2 clients (out of 2)\n",
      "\u001b[91mERROR 2025-07-12 23:24:15,530\u001b[0m:     An exception was raised when processing a message by RayBackend\n",
      "\u001b[91mERROR 2025-07-12 23:24:15,531\u001b[0m:     local variable 'future' referenced before assignment\n",
      "\u001b[91mERROR 2025-07-12 23:24:15,531\u001b[0m:     Traceback (most recent call last):\n",
      "  File \"d:\\Anaconda\\envs\\TMenv\\lib\\site-packages\\flwr\\server\\superlink\\fleet\\vce\\backend\\raybackend.py\", line 166, in process_message\n",
      "    future = self.pool.submit(\n",
      "  File \"d:\\Anaconda\\envs\\TMenv\\lib\\site-packages\\flwr\\simulation\\ray_transport\\ray_actor.py\", line 460, in submit\n",
      "    actor = self.pool.pop()\n",
      "IndexError: pop from empty list\n",
      "\n",
      "During handling of the above exception, another exception occurred:\n",
      "\n",
      "Traceback (most recent call last):\n",
      "  File \"d:\\Anaconda\\envs\\TMenv\\lib\\site-packages\\flwr\\server\\superlink\\fleet\\vce\\vce_api.py\", line 112, in worker\n",
      "    out_mssg, updated_context = backend.process_message(message, context)\n",
      "  File \"d:\\Anaconda\\envs\\TMenv\\lib\\site-packages\\flwr\\server\\superlink\\fleet\\vce\\backend\\raybackend.py\", line 186, in process_message\n",
      "    self.pool.add_actor_back_to_pool(future)\n",
      "UnboundLocalError: local variable 'future' referenced before assignment\n",
      "\n",
      "\u001b[91mERROR 2025-07-12 23:24:15,532\u001b[0m:     An exception was raised when processing a message by RayBackend\n",
      "\u001b[91mERROR 2025-07-12 23:24:15,532\u001b[0m:     local variable 'future' referenced before assignment\n",
      "\u001b[91mERROR 2025-07-12 23:24:15,533\u001b[0m:     Traceback (most recent call last):\n",
      "  File \"d:\\Anaconda\\envs\\TMenv\\lib\\site-packages\\flwr\\server\\superlink\\fleet\\vce\\backend\\raybackend.py\", line 166, in process_message\n",
      "    future = self.pool.submit(\n",
      "  File \"d:\\Anaconda\\envs\\TMenv\\lib\\site-packages\\flwr\\simulation\\ray_transport\\ray_actor.py\", line 460, in submit\n",
      "    actor = self.pool.pop()\n",
      "IndexError: pop from empty list\n",
      "\n",
      "During handling of the above exception, another exception occurred:\n",
      "\n",
      "Traceback (most recent call last):\n",
      "  File \"d:\\Anaconda\\envs\\TMenv\\lib\\site-packages\\flwr\\server\\superlink\\fleet\\vce\\vce_api.py\", line 112, in worker\n",
      "    out_mssg, updated_context = backend.process_message(message, context)\n",
      "  File \"d:\\Anaconda\\envs\\TMenv\\lib\\site-packages\\flwr\\server\\superlink\\fleet\\vce\\backend\\raybackend.py\", line 186, in process_message\n",
      "    self.pool.add_actor_back_to_pool(future)\n",
      "UnboundLocalError: local variable 'future' referenced before assignment\n",
      "\n",
      "\u001b[92mINFO 2025-07-12 23:24:15,561\u001b[0m:      aggregate_fit: received 0 results and 2 failures\n",
      "\u001b[92mINFO 2025-07-12 23:24:15,562\u001b[0m:      configure_evaluate: strategy sampled 2 clients (out of 2)\n",
      "\u001b[91mERROR 2025-07-12 23:24:15,638\u001b[0m:     An exception was raised when processing a message by RayBackend\n",
      "\u001b[91mERROR 2025-07-12 23:24:15,638\u001b[0m:     local variable 'future' referenced before assignment\n",
      "\u001b[91mERROR 2025-07-12 23:24:15,639\u001b[0m:     Traceback (most recent call last):\n",
      "  File \"d:\\Anaconda\\envs\\TMenv\\lib\\site-packages\\flwr\\server\\superlink\\fleet\\vce\\backend\\raybackend.py\", line 166, in process_message\n",
      "    future = self.pool.submit(\n",
      "  File \"d:\\Anaconda\\envs\\TMenv\\lib\\site-packages\\flwr\\simulation\\ray_transport\\ray_actor.py\", line 460, in submit\n",
      "    actor = self.pool.pop()\n",
      "IndexError: pop from empty list\n",
      "\n",
      "During handling of the above exception, another exception occurred:\n",
      "\n",
      "Traceback (most recent call last):\n",
      "  File \"d:\\Anaconda\\envs\\TMenv\\lib\\site-packages\\flwr\\server\\superlink\\fleet\\vce\\vce_api.py\", line 112, in worker\n",
      "    out_mssg, updated_context = backend.process_message(message, context)\n",
      "  File \"d:\\Anaconda\\envs\\TMenv\\lib\\site-packages\\flwr\\server\\superlink\\fleet\\vce\\backend\\raybackend.py\", line 186, in process_message\n",
      "    self.pool.add_actor_back_to_pool(future)\n",
      "UnboundLocalError: local variable 'future' referenced before assignment\n",
      "\n",
      "\u001b[91mERROR 2025-07-12 23:24:15,640\u001b[0m:     An exception was raised when processing a message by RayBackend\n",
      "\u001b[91mERROR 2025-07-12 23:24:15,640\u001b[0m:     local variable 'future' referenced before assignment\n",
      "\u001b[91mERROR 2025-07-12 23:24:15,641\u001b[0m:     Traceback (most recent call last):\n",
      "  File \"d:\\Anaconda\\envs\\TMenv\\lib\\site-packages\\flwr\\server\\superlink\\fleet\\vce\\backend\\raybackend.py\", line 166, in process_message\n",
      "    future = self.pool.submit(\n",
      "  File \"d:\\Anaconda\\envs\\TMenv\\lib\\site-packages\\flwr\\simulation\\ray_transport\\ray_actor.py\", line 460, in submit\n",
      "    actor = self.pool.pop()\n",
      "IndexError: pop from empty list\n",
      "\n",
      "During handling of the above exception, another exception occurred:\n",
      "\n",
      "Traceback (most recent call last):\n",
      "  File \"d:\\Anaconda\\envs\\TMenv\\lib\\site-packages\\flwr\\server\\superlink\\fleet\\vce\\vce_api.py\", line 112, in worker\n",
      "    out_mssg, updated_context = backend.process_message(message, context)\n",
      "  File \"d:\\Anaconda\\envs\\TMenv\\lib\\site-packages\\flwr\\server\\superlink\\fleet\\vce\\backend\\raybackend.py\", line 186, in process_message\n",
      "    self.pool.add_actor_back_to_pool(future)\n",
      "UnboundLocalError: local variable 'future' referenced before assignment\n",
      "\n",
      "\u001b[92mINFO 2025-07-12 23:24:15,669\u001b[0m:      aggregate_evaluate: received 0 results and 2 failures\n",
      "\u001b[92mINFO 2025-07-12 23:24:15,670\u001b[0m:      \n",
      "\u001b[92mINFO 2025-07-12 23:24:15,671\u001b[0m:      [ROUND 28]\n",
      "\u001b[92mINFO 2025-07-12 23:24:15,671\u001b[0m:      configure_fit: strategy sampled 2 clients (out of 2)\n",
      "\u001b[91mERROR 2025-07-12 23:24:15,745\u001b[0m:     An exception was raised when processing a message by RayBackend\n",
      "\u001b[91mERROR 2025-07-12 23:24:15,746\u001b[0m:     local variable 'future' referenced before assignment\n",
      "\u001b[91mERROR 2025-07-12 23:24:15,748\u001b[0m:     Traceback (most recent call last):\n",
      "  File \"d:\\Anaconda\\envs\\TMenv\\lib\\site-packages\\flwr\\server\\superlink\\fleet\\vce\\backend\\raybackend.py\", line 166, in process_message\n",
      "    future = self.pool.submit(\n",
      "  File \"d:\\Anaconda\\envs\\TMenv\\lib\\site-packages\\flwr\\simulation\\ray_transport\\ray_actor.py\", line 460, in submit\n",
      "    actor = self.pool.pop()\n",
      "IndexError: pop from empty list\n",
      "\n",
      "During handling of the above exception, another exception occurred:\n",
      "\n",
      "Traceback (most recent call last):\n",
      "  File \"d:\\Anaconda\\envs\\TMenv\\lib\\site-packages\\flwr\\server\\superlink\\fleet\\vce\\vce_api.py\", line 112, in worker\n",
      "    out_mssg, updated_context = backend.process_message(message, context)\n",
      "  File \"d:\\Anaconda\\envs\\TMenv\\lib\\site-packages\\flwr\\server\\superlink\\fleet\\vce\\backend\\raybackend.py\", line 186, in process_message\n",
      "    self.pool.add_actor_back_to_pool(future)\n",
      "UnboundLocalError: local variable 'future' referenced before assignment\n",
      "\n",
      "\u001b[91mERROR 2025-07-12 23:24:15,748\u001b[0m:     An exception was raised when processing a message by RayBackend\n",
      "\u001b[91mERROR 2025-07-12 23:24:15,749\u001b[0m:     local variable 'future' referenced before assignment\n",
      "\u001b[91mERROR 2025-07-12 23:24:15,750\u001b[0m:     Traceback (most recent call last):\n",
      "  File \"d:\\Anaconda\\envs\\TMenv\\lib\\site-packages\\flwr\\server\\superlink\\fleet\\vce\\backend\\raybackend.py\", line 166, in process_message\n",
      "    future = self.pool.submit(\n",
      "  File \"d:\\Anaconda\\envs\\TMenv\\lib\\site-packages\\flwr\\simulation\\ray_transport\\ray_actor.py\", line 460, in submit\n",
      "    actor = self.pool.pop()\n",
      "IndexError: pop from empty list\n",
      "\n",
      "During handling of the above exception, another exception occurred:\n",
      "\n",
      "Traceback (most recent call last):\n",
      "  File \"d:\\Anaconda\\envs\\TMenv\\lib\\site-packages\\flwr\\server\\superlink\\fleet\\vce\\vce_api.py\", line 112, in worker\n",
      "    out_mssg, updated_context = backend.process_message(message, context)\n",
      "  File \"d:\\Anaconda\\envs\\TMenv\\lib\\site-packages\\flwr\\server\\superlink\\fleet\\vce\\backend\\raybackend.py\", line 186, in process_message\n",
      "    self.pool.add_actor_back_to_pool(future)\n",
      "UnboundLocalError: local variable 'future' referenced before assignment\n",
      "\n",
      "\u001b[92mINFO 2025-07-12 23:24:15,776\u001b[0m:      aggregate_fit: received 0 results and 2 failures\n",
      "\u001b[92mINFO 2025-07-12 23:24:15,777\u001b[0m:      configure_evaluate: strategy sampled 2 clients (out of 2)\n",
      "\u001b[91mERROR 2025-07-12 23:24:15,853\u001b[0m:     An exception was raised when processing a message by RayBackend\n",
      "\u001b[91mERROR 2025-07-12 23:24:15,854\u001b[0m:     local variable 'future' referenced before assignment\n",
      "\u001b[91mERROR 2025-07-12 23:24:15,855\u001b[0m:     Traceback (most recent call last):\n",
      "  File \"d:\\Anaconda\\envs\\TMenv\\lib\\site-packages\\flwr\\server\\superlink\\fleet\\vce\\backend\\raybackend.py\", line 166, in process_message\n",
      "    future = self.pool.submit(\n",
      "  File \"d:\\Anaconda\\envs\\TMenv\\lib\\site-packages\\flwr\\simulation\\ray_transport\\ray_actor.py\", line 460, in submit\n",
      "    actor = self.pool.pop()\n",
      "IndexError: pop from empty list\n",
      "\n",
      "During handling of the above exception, another exception occurred:\n",
      "\n",
      "Traceback (most recent call last):\n",
      "  File \"d:\\Anaconda\\envs\\TMenv\\lib\\site-packages\\flwr\\server\\superlink\\fleet\\vce\\vce_api.py\", line 112, in worker\n",
      "    out_mssg, updated_context = backend.process_message(message, context)\n",
      "  File \"d:\\Anaconda\\envs\\TMenv\\lib\\site-packages\\flwr\\server\\superlink\\fleet\\vce\\backend\\raybackend.py\", line 186, in process_message\n",
      "    self.pool.add_actor_back_to_pool(future)\n",
      "UnboundLocalError: local variable 'future' referenced before assignment\n",
      "\n",
      "\u001b[91mERROR 2025-07-12 23:24:15,855\u001b[0m:     An exception was raised when processing a message by RayBackend\n",
      "\u001b[91mERROR 2025-07-12 23:24:15,856\u001b[0m:     local variable 'future' referenced before assignment\n",
      "\u001b[91mERROR 2025-07-12 23:24:15,857\u001b[0m:     Traceback (most recent call last):\n",
      "  File \"d:\\Anaconda\\envs\\TMenv\\lib\\site-packages\\flwr\\server\\superlink\\fleet\\vce\\backend\\raybackend.py\", line 166, in process_message\n",
      "    future = self.pool.submit(\n",
      "  File \"d:\\Anaconda\\envs\\TMenv\\lib\\site-packages\\flwr\\simulation\\ray_transport\\ray_actor.py\", line 460, in submit\n",
      "    actor = self.pool.pop()\n",
      "IndexError: pop from empty list\n",
      "\n",
      "During handling of the above exception, another exception occurred:\n",
      "\n",
      "Traceback (most recent call last):\n",
      "  File \"d:\\Anaconda\\envs\\TMenv\\lib\\site-packages\\flwr\\server\\superlink\\fleet\\vce\\vce_api.py\", line 112, in worker\n",
      "    out_mssg, updated_context = backend.process_message(message, context)\n",
      "  File \"d:\\Anaconda\\envs\\TMenv\\lib\\site-packages\\flwr\\server\\superlink\\fleet\\vce\\backend\\raybackend.py\", line 186, in process_message\n",
      "    self.pool.add_actor_back_to_pool(future)\n",
      "UnboundLocalError: local variable 'future' referenced before assignment\n",
      "\n",
      "\u001b[92mINFO 2025-07-12 23:24:15,883\u001b[0m:      aggregate_evaluate: received 0 results and 2 failures\n",
      "\u001b[92mINFO 2025-07-12 23:24:15,884\u001b[0m:      \n",
      "\u001b[92mINFO 2025-07-12 23:24:15,886\u001b[0m:      [ROUND 29]\n",
      "\u001b[92mINFO 2025-07-12 23:24:15,886\u001b[0m:      configure_fit: strategy sampled 2 clients (out of 2)\n",
      "\u001b[91mERROR 2025-07-12 23:24:15,960\u001b[0m:     An exception was raised when processing a message by RayBackend\n",
      "\u001b[91mERROR 2025-07-12 23:24:15,961\u001b[0m:     local variable 'future' referenced before assignment\n",
      "\u001b[91mERROR 2025-07-12 23:24:15,962\u001b[0m:     Traceback (most recent call last):\n",
      "  File \"d:\\Anaconda\\envs\\TMenv\\lib\\site-packages\\flwr\\server\\superlink\\fleet\\vce\\backend\\raybackend.py\", line 166, in process_message\n",
      "    future = self.pool.submit(\n",
      "  File \"d:\\Anaconda\\envs\\TMenv\\lib\\site-packages\\flwr\\simulation\\ray_transport\\ray_actor.py\", line 460, in submit\n",
      "    actor = self.pool.pop()\n",
      "IndexError: pop from empty list\n",
      "\n",
      "During handling of the above exception, another exception occurred:\n",
      "\n",
      "Traceback (most recent call last):\n",
      "  File \"d:\\Anaconda\\envs\\TMenv\\lib\\site-packages\\flwr\\server\\superlink\\fleet\\vce\\vce_api.py\", line 112, in worker\n",
      "    out_mssg, updated_context = backend.process_message(message, context)\n",
      "  File \"d:\\Anaconda\\envs\\TMenv\\lib\\site-packages\\flwr\\server\\superlink\\fleet\\vce\\backend\\raybackend.py\", line 186, in process_message\n",
      "    self.pool.add_actor_back_to_pool(future)\n",
      "UnboundLocalError: local variable 'future' referenced before assignment\n",
      "\n",
      "\u001b[91mERROR 2025-07-12 23:24:15,964\u001b[0m:     An exception was raised when processing a message by RayBackend\n",
      "\u001b[91mERROR 2025-07-12 23:24:15,964\u001b[0m:     local variable 'future' referenced before assignment\n",
      "\u001b[91mERROR 2025-07-12 23:24:15,966\u001b[0m:     Traceback (most recent call last):\n",
      "  File \"d:\\Anaconda\\envs\\TMenv\\lib\\site-packages\\flwr\\server\\superlink\\fleet\\vce\\backend\\raybackend.py\", line 166, in process_message\n",
      "    future = self.pool.submit(\n",
      "  File \"d:\\Anaconda\\envs\\TMenv\\lib\\site-packages\\flwr\\simulation\\ray_transport\\ray_actor.py\", line 460, in submit\n",
      "    actor = self.pool.pop()\n",
      "IndexError: pop from empty list\n",
      "\n",
      "During handling of the above exception, another exception occurred:\n",
      "\n",
      "Traceback (most recent call last):\n",
      "  File \"d:\\Anaconda\\envs\\TMenv\\lib\\site-packages\\flwr\\server\\superlink\\fleet\\vce\\vce_api.py\", line 112, in worker\n",
      "    out_mssg, updated_context = backend.process_message(message, context)\n",
      "  File \"d:\\Anaconda\\envs\\TMenv\\lib\\site-packages\\flwr\\server\\superlink\\fleet\\vce\\backend\\raybackend.py\", line 186, in process_message\n",
      "    self.pool.add_actor_back_to_pool(future)\n",
      "UnboundLocalError: local variable 'future' referenced before assignment\n",
      "\n",
      "\u001b[92mINFO 2025-07-12 23:24:15,990\u001b[0m:      aggregate_fit: received 0 results and 2 failures\n",
      "\u001b[92mINFO 2025-07-12 23:24:15,991\u001b[0m:      configure_evaluate: strategy sampled 2 clients (out of 2)\n",
      "\u001b[91mERROR 2025-07-12 23:24:16,068\u001b[0m:     An exception was raised when processing a message by RayBackend\n",
      "\u001b[91mERROR 2025-07-12 23:24:16,069\u001b[0m:     local variable 'future' referenced before assignment\n",
      "\u001b[91mERROR 2025-07-12 23:24:16,070\u001b[0m:     Traceback (most recent call last):\n",
      "  File \"d:\\Anaconda\\envs\\TMenv\\lib\\site-packages\\flwr\\server\\superlink\\fleet\\vce\\backend\\raybackend.py\", line 166, in process_message\n",
      "    future = self.pool.submit(\n",
      "  File \"d:\\Anaconda\\envs\\TMenv\\lib\\site-packages\\flwr\\simulation\\ray_transport\\ray_actor.py\", line 460, in submit\n",
      "    actor = self.pool.pop()\n",
      "IndexError: pop from empty list\n",
      "\n",
      "During handling of the above exception, another exception occurred:\n",
      "\n",
      "Traceback (most recent call last):\n",
      "  File \"d:\\Anaconda\\envs\\TMenv\\lib\\site-packages\\flwr\\server\\superlink\\fleet\\vce\\vce_api.py\", line 112, in worker\n",
      "    out_mssg, updated_context = backend.process_message(message, context)\n",
      "  File \"d:\\Anaconda\\envs\\TMenv\\lib\\site-packages\\flwr\\server\\superlink\\fleet\\vce\\backend\\raybackend.py\", line 186, in process_message\n",
      "    self.pool.add_actor_back_to_pool(future)\n",
      "UnboundLocalError: local variable 'future' referenced before assignment\n",
      "\n",
      "\u001b[91mERROR 2025-07-12 23:24:16,071\u001b[0m:     An exception was raised when processing a message by RayBackend\n",
      "\u001b[91mERROR 2025-07-12 23:24:16,072\u001b[0m:     local variable 'future' referenced before assignment\n",
      "\u001b[91mERROR 2025-07-12 23:24:16,074\u001b[0m:     Traceback (most recent call last):\n",
      "  File \"d:\\Anaconda\\envs\\TMenv\\lib\\site-packages\\flwr\\server\\superlink\\fleet\\vce\\backend\\raybackend.py\", line 166, in process_message\n",
      "    future = self.pool.submit(\n",
      "  File \"d:\\Anaconda\\envs\\TMenv\\lib\\site-packages\\flwr\\simulation\\ray_transport\\ray_actor.py\", line 460, in submit\n",
      "    actor = self.pool.pop()\n",
      "IndexError: pop from empty list\n",
      "\n",
      "During handling of the above exception, another exception occurred:\n",
      "\n",
      "Traceback (most recent call last):\n",
      "  File \"d:\\Anaconda\\envs\\TMenv\\lib\\site-packages\\flwr\\server\\superlink\\fleet\\vce\\vce_api.py\", line 112, in worker\n",
      "    out_mssg, updated_context = backend.process_message(message, context)\n",
      "  File \"d:\\Anaconda\\envs\\TMenv\\lib\\site-packages\\flwr\\server\\superlink\\fleet\\vce\\backend\\raybackend.py\", line 186, in process_message\n",
      "    self.pool.add_actor_back_to_pool(future)\n",
      "UnboundLocalError: local variable 'future' referenced before assignment\n",
      "\n",
      "\u001b[92mINFO 2025-07-12 23:24:16,098\u001b[0m:      aggregate_evaluate: received 0 results and 2 failures\n",
      "\u001b[92mINFO 2025-07-12 23:24:16,099\u001b[0m:      \n",
      "\u001b[92mINFO 2025-07-12 23:24:16,100\u001b[0m:      [ROUND 30]\n",
      "\u001b[92mINFO 2025-07-12 23:24:16,100\u001b[0m:      configure_fit: strategy sampled 2 clients (out of 2)\n",
      "\u001b[91mERROR 2025-07-12 23:24:16,174\u001b[0m:     An exception was raised when processing a message by RayBackend\n",
      "\u001b[91mERROR 2025-07-12 23:24:16,175\u001b[0m:     local variable 'future' referenced before assignment\n",
      "\u001b[91mERROR 2025-07-12 23:24:16,176\u001b[0m:     Traceback (most recent call last):\n",
      "  File \"d:\\Anaconda\\envs\\TMenv\\lib\\site-packages\\flwr\\server\\superlink\\fleet\\vce\\backend\\raybackend.py\", line 166, in process_message\n",
      "    future = self.pool.submit(\n",
      "  File \"d:\\Anaconda\\envs\\TMenv\\lib\\site-packages\\flwr\\simulation\\ray_transport\\ray_actor.py\", line 460, in submit\n",
      "    actor = self.pool.pop()\n",
      "IndexError: pop from empty list\n",
      "\n",
      "During handling of the above exception, another exception occurred:\n",
      "\n",
      "Traceback (most recent call last):\n",
      "  File \"d:\\Anaconda\\envs\\TMenv\\lib\\site-packages\\flwr\\server\\superlink\\fleet\\vce\\vce_api.py\", line 112, in worker\n",
      "    out_mssg, updated_context = backend.process_message(message, context)\n",
      "  File \"d:\\Anaconda\\envs\\TMenv\\lib\\site-packages\\flwr\\server\\superlink\\fleet\\vce\\backend\\raybackend.py\", line 186, in process_message\n",
      "    self.pool.add_actor_back_to_pool(future)\n",
      "UnboundLocalError: local variable 'future' referenced before assignment\n",
      "\n",
      "\u001b[91mERROR 2025-07-12 23:24:16,177\u001b[0m:     An exception was raised when processing a message by RayBackend\n",
      "\u001b[91mERROR 2025-07-12 23:24:16,177\u001b[0m:     local variable 'future' referenced before assignment\n",
      "\u001b[91mERROR 2025-07-12 23:24:16,178\u001b[0m:     Traceback (most recent call last):\n",
      "  File \"d:\\Anaconda\\envs\\TMenv\\lib\\site-packages\\flwr\\server\\superlink\\fleet\\vce\\backend\\raybackend.py\", line 166, in process_message\n",
      "    future = self.pool.submit(\n",
      "  File \"d:\\Anaconda\\envs\\TMenv\\lib\\site-packages\\flwr\\simulation\\ray_transport\\ray_actor.py\", line 460, in submit\n",
      "    actor = self.pool.pop()\n",
      "IndexError: pop from empty list\n",
      "\n",
      "During handling of the above exception, another exception occurred:\n",
      "\n",
      "Traceback (most recent call last):\n",
      "  File \"d:\\Anaconda\\envs\\TMenv\\lib\\site-packages\\flwr\\server\\superlink\\fleet\\vce\\vce_api.py\", line 112, in worker\n",
      "    out_mssg, updated_context = backend.process_message(message, context)\n",
      "  File \"d:\\Anaconda\\envs\\TMenv\\lib\\site-packages\\flwr\\server\\superlink\\fleet\\vce\\backend\\raybackend.py\", line 186, in process_message\n",
      "    self.pool.add_actor_back_to_pool(future)\n",
      "UnboundLocalError: local variable 'future' referenced before assignment\n",
      "\n",
      "\u001b[92mINFO 2025-07-12 23:24:16,205\u001b[0m:      aggregate_fit: received 0 results and 2 failures\n",
      "\u001b[92mINFO 2025-07-12 23:24:16,206\u001b[0m:      configure_evaluate: strategy sampled 2 clients (out of 2)\n",
      "\u001b[91mERROR 2025-07-12 23:24:16,283\u001b[0m:     An exception was raised when processing a message by RayBackend\n",
      "\u001b[91mERROR 2025-07-12 23:24:16,284\u001b[0m:     local variable 'future' referenced before assignment\n",
      "\u001b[91mERROR 2025-07-12 23:24:16,285\u001b[0m:     Traceback (most recent call last):\n",
      "  File \"d:\\Anaconda\\envs\\TMenv\\lib\\site-packages\\flwr\\server\\superlink\\fleet\\vce\\backend\\raybackend.py\", line 166, in process_message\n",
      "    future = self.pool.submit(\n",
      "  File \"d:\\Anaconda\\envs\\TMenv\\lib\\site-packages\\flwr\\simulation\\ray_transport\\ray_actor.py\", line 460, in submit\n",
      "    actor = self.pool.pop()\n",
      "IndexError: pop from empty list\n",
      "\n",
      "During handling of the above exception, another exception occurred:\n",
      "\n",
      "Traceback (most recent call last):\n",
      "  File \"d:\\Anaconda\\envs\\TMenv\\lib\\site-packages\\flwr\\server\\superlink\\fleet\\vce\\vce_api.py\", line 112, in worker\n",
      "    out_mssg, updated_context = backend.process_message(message, context)\n",
      "  File \"d:\\Anaconda\\envs\\TMenv\\lib\\site-packages\\flwr\\server\\superlink\\fleet\\vce\\backend\\raybackend.py\", line 186, in process_message\n",
      "    self.pool.add_actor_back_to_pool(future)\n",
      "UnboundLocalError: local variable 'future' referenced before assignment\n",
      "\n",
      "\u001b[91mERROR 2025-07-12 23:24:16,285\u001b[0m:     An exception was raised when processing a message by RayBackend\n",
      "\u001b[91mERROR 2025-07-12 23:24:16,286\u001b[0m:     local variable 'future' referenced before assignment\n",
      "\u001b[91mERROR 2025-07-12 23:24:16,287\u001b[0m:     Traceback (most recent call last):\n",
      "  File \"d:\\Anaconda\\envs\\TMenv\\lib\\site-packages\\flwr\\server\\superlink\\fleet\\vce\\backend\\raybackend.py\", line 166, in process_message\n",
      "    future = self.pool.submit(\n",
      "  File \"d:\\Anaconda\\envs\\TMenv\\lib\\site-packages\\flwr\\simulation\\ray_transport\\ray_actor.py\", line 460, in submit\n",
      "    actor = self.pool.pop()\n",
      "IndexError: pop from empty list\n",
      "\n",
      "During handling of the above exception, another exception occurred:\n",
      "\n",
      "Traceback (most recent call last):\n",
      "  File \"d:\\Anaconda\\envs\\TMenv\\lib\\site-packages\\flwr\\server\\superlink\\fleet\\vce\\vce_api.py\", line 112, in worker\n",
      "    out_mssg, updated_context = backend.process_message(message, context)\n",
      "  File \"d:\\Anaconda\\envs\\TMenv\\lib\\site-packages\\flwr\\server\\superlink\\fleet\\vce\\backend\\raybackend.py\", line 186, in process_message\n",
      "    self.pool.add_actor_back_to_pool(future)\n",
      "UnboundLocalError: local variable 'future' referenced before assignment\n",
      "\n",
      "\u001b[92mINFO 2025-07-12 23:24:16,314\u001b[0m:      aggregate_evaluate: received 0 results and 2 failures\n",
      "\u001b[92mINFO 2025-07-12 23:24:16,316\u001b[0m:      \n",
      "\u001b[92mINFO 2025-07-12 23:24:16,316\u001b[0m:      [SUMMARY]\n",
      "\u001b[92mINFO 2025-07-12 23:24:16,317\u001b[0m:      Run finished 30 round(s) in 144.01s\n",
      "\u001b[92mINFO 2025-07-12 23:24:16,318\u001b[0m:      \tHistory (loss, distributed):\n",
      "\u001b[92mINFO 2025-07-12 23:24:16,318\u001b[0m:      \t\tround 1: -1.0\n",
      "\u001b[92mINFO 2025-07-12 23:24:16,319\u001b[0m:      \t\tround 2: -1.0\n",
      "\u001b[92mINFO 2025-07-12 23:24:16,319\u001b[0m:      \t\tround 3: -1.0\n",
      "\u001b[92mINFO 2025-07-12 23:24:16,320\u001b[0m:      \t\tround 4: -1.0\n",
      "\u001b[92mINFO 2025-07-12 23:24:16,320\u001b[0m:      \t\tround 5: -1.0\n",
      "\u001b[92mINFO 2025-07-12 23:24:16,321\u001b[0m:      \t\tround 6: -1.0\n",
      "\u001b[92mINFO 2025-07-12 23:24:16,321\u001b[0m:      \t\tround 7: -1.0\n",
      "\u001b[92mINFO 2025-07-12 23:24:16,321\u001b[0m:      \n",
      "\u001b[94mDEBUG 2025-07-12 23:24:16,324\u001b[0m:     ServerApp finished running.\n",
      "\u001b[94mDEBUG 2025-07-12 23:24:16,325\u001b[0m:     ServerApp finished running.\n",
      "\u001b[94mDEBUG 2025-07-12 23:24:16,325\u001b[0m:     Triggered stop event for Simulation Engine.\n",
      "\u001b[94mDEBUG 2025-07-12 23:24:17,289\u001b[0m:     Terminated 0 actors\n",
      "\u001b[33m(raylet)\u001b[0m unknown\u001b[32m [repeated 25x across cluster] (Ray deduplicates logs by default. Set RAY_DEDUP_LOGS=0 to disable log deduplication, or see https://docs.ray.io/en/master/ray-observability/user-guides/configure-logging.html#log-deduplication for more options.)\u001b[0m\n",
      "\u001b[94mDEBUG 2025-07-12 23:24:17,841\u001b[0m:     Terminated RayBackend\n",
      "\u001b[94mDEBUG 2025-07-12 23:24:17,842\u001b[0m:     Stopping Simulation Engine now.\n"
     ]
    }
   ],
   "source": [
    "# Run simulation\n",
    "run_simulation(\n",
    "    server_app=server,\n",
    "    client_app=client,\n",
    "    num_supernodes=NUM_CLIENTS,\n",
    "    backend_config=backend_config,\n",
    "    verbose_logging=True\n",
    ")"
   ]
  }
 ],
 "metadata": {
  "kernelspec": {
   "display_name": "TMenv",
   "language": "python",
   "name": "python3"
  },
  "language_info": {
   "codemirror_mode": {
    "name": "ipython",
    "version": 3
   },
   "file_extension": ".py",
   "mimetype": "text/x-python",
   "name": "python",
   "nbconvert_exporter": "python",
   "pygments_lexer": "ipython3",
   "version": "3.9.21"
  }
 },
 "nbformat": 4,
 "nbformat_minor": 5
}
